Workbook
Name LOT_BENECEL: '25 2026 LOT BAĞI'!$T$2:$T$2
Name LOT_KARABIBER: '25 2026 LOT BAĞI'!$R$2:$R$4
Name LOT_MISIR: '25 2026 LOT BAĞI'!$O$2:$O$4
Name LOT_NISASTA: '25 2026 LOT BAĞI'!$N$2:$N$3
Name LOT_PATATES: '25 2026 LOT BAĞI'!$M$2:$M$3
Name LOT_SARIMSAK: '25 2026 LOT BAĞI'!$Q$2:$Q$3
Name LOT_SAVOUR: '25 2026 LOT BAĞI'!$P$2:$P$2
Name LOT_TUZ: '25 2026 LOT BAĞI'!$S$2:$S$3

Sheet 00 ANA SAYFA
A1: REDBOX GIDA SANAYİ VE TİC. LTD. ŞTİ.
A2: LONG POTATO — 2026 CANLI YÖNETİM PANELİ
A4: OPERASYON AKIŞI | B4: 1. DEPO KABUL | C4: → | D4: 2. ÜRETİM | E4: → | F4: 3. PAKETLEME | G4: → | H4: 4. SEVKİYAT | I4: → | J4: 5. İZLENEBİLİRLİK
A6: Kabul edilen hammadde lotu | B6: =COUNTA('20 2026 DEPO KABUL'!F2:F501) -> 16 | D6: Kabul kaydı | E6: =COUNTIF('20 2026 DEPO KABUL'!I2:I501,"KABUL") -> 9
A8: Toplam üretim günü | B8: =COUNTA('21 2026 ÜRETİM'!A2:A501) -> 11 | D8: 2026 SEVK NOKTASI | E8: KG | G8: SEVK NOKTASI | H8: TOPLAM PAKET | I8: AMBALAJ | J8: TOPLAM KG
A9: Toplam parti | B9: =SUM('21 2026 ÜRETİM'!B2:B501) -> 121 | D9: File Market | E9: =SUMIF('23 2026 SEVKİYAT'!$B$2:$B$501,D9,'23 2026 SEVKİYAT'!$H$2:$H$501) -> 1440 | G9: File Market | H9: =SUMIFS('23 2026 SEVKİYAT'!$G$2:$G$501,'23 2026 SEVKİYAT'!$B$2:$B$501,G5,'23 2026 SEVKİYAT'!$F$2:$F$501,I5) -> 0 | I9: 500 g | J9: =SUMIFS('23 2026 SEVKİYAT'!$H$2:$H$501,'23 2026 SEVKİYAT'!$B$2:$B$501,G5,'23 2026 SEVKİYAT'!$F$2:$F$501,I5) -> 0
A10: Teorik üretim kg | B10: =SUM('21 2026 ÜRETİM'!D2:D501) -> 2469.852 | D10: Şehzade Market | E10: =SUMIF('23 2026 SEVKİYAT'!$B$2:$B$501,D10,'23 2026 SEVKİYAT'!$H$2:$H$501) -> 512 | G10: Şehzade Market | H10: =SUMIFS('23 2026 SEVKİYAT'!$G$2:$G$501,'23 2026 SEVKİYAT'!$B$2:$B$501,G6,'23 2026 SEVKİYAT'!$F$2:$F$501,I6) -> 0 | I10: 500 g | J10: =SUMIFS('23 2026 SEVKİYAT'!$H$2:$H$501,'23 2026 SEVKİYAT'!$B$2:$B$501,G6,'23 2026 SEVKİYAT'!$F$2:$F$501,I6) -> 0
A11: Üretim firesi kg | B11: =SUM('21 2026 ÜRETİM'!E2:E501) -> 103 | D11: Malatya Alek Gıda | E11: =SUMIF('23 2026 SEVKİYAT'!$B$2:$B$501,D11,'23 2026 SEVKİYAT'!$H$2:$H$501) -> 100 | G11: Malatya Alek Gıda | H11: =SUMIFS('23 2026 SEVKİYAT'!$G$2:$G$501,'23 2026 SEVKİYAT'!$B$2:$B$501,G7,'23 2026 SEVKİYAT'!$F$2:$F$501,I7) -> 0 | I11: 2,5 kg | J11: =SUMIFS('23 2026 SEVKİYAT'!$H$2:$H$501,'23 2026 SEVKİYAT'!$B$2:$B$501,G7,'23 2026 SEVKİYAT'!$F$2:$F$501,I7) -> 0
A12: Net mamul kg | B12: =SUM('21 2026 ÜRETİM'!F2:F501) -> 2366.496 | D12: Fuar aracı | E12: =SUMIF('23 2026 SEVKİYAT'!$B$2:$B$501,D12,'23 2026 SEVKİYAT'!$H$2:$H$501) -> 45 | G12: Fuar aracı | H12: =SUMIFS('23 2026 SEVKİYAT'!$G$2:$G$501,'23 2026 SEVKİYAT'!$B$2:$B$501,G8,'23 2026 SEVKİYAT'!$F$2:$F$501,I8) -> 0 | I12: 2,5 kg | J12: =SUMIFS('23 2026 SEVKİYAT'!$H$2:$H$501,'23 2026 SEVKİYAT'!$B$2:$B$501,G8,'23 2026 SEVKİYAT'!$F$2:$F$501,I8) -> 0
A13: 500 g paket adedi | B13: =SUM('22 2026 PAKETLEME'!D2:D501) -> 4154 | D13: Festival / Fuar | E13: =SUMIF('23 2026 SEVKİYAT'!$B$2:$B$501,D13,'23 2026 SEVKİYAT'!$H$2:$H$501) -> 140 | G13: Festival / Fuar | H13: =SUMIFS('23 2026 SEVKİYAT'!$G$2:$G$501,'23 2026 SEVKİYAT'!$B$2:$B$501,G9,'23 2026 SEVKİYAT'!$F$2:$F$501,I9) -> 2880 | I13: 2,5 kg | J13: =SUMIFS('23 2026 SEVKİYAT'!$H$2:$H$501,'23 2026 SEVKİYAT'!$B$2:$B$501,G9,'23 2026 SEVKİYAT'!$F$2:$F$501,I9) -> 1440
A14: 500 g paketlenen kg | B14: =SUM('22 2026 PAKETLEME'!E2:E501) -> 2077 | D14: Samsun Terme Fuarı | E14: =SUMIF('23 2026 SEVKİYAT'!$B$2:$B$501,D14,'23 2026 SEVKİYAT'!$H$2:$H$501) -> 114 | G14: Samsun Terme Fuarı | H14: TEYİT | I14: 2,5 kg | J14: =SUMIF('23 2026 SEVKİYAT'!$B$2:$B$501,G10,'23 2026 SEVKİYAT'!$H$2:$H$501) -> 512
A15: 2,5 kg paket adedi | B15: =SUM('22 2026 PAKETLEME'!F2:F501) -> 114 | D15: KÜTLE DENKLİĞİ KONTROLÜ | E15: DEĞER
A16: 2,5 kg paketlenen kg | B16: =SUM('22 2026 PAKETLEME'!G2:G501) -> 285 | D16: Kontrol edilen üretim | E16: =COUNTA('24 2026 KÜTLE DENKLİĞİ'!A2:A501) -> 500
A17: Paketleme firesi kg | B17: =SUM('22 2026 PAKETLEME'!H2:H501) -> 4.496 | D17: Kapalı denklik | E17: =COUNTIF('24 2026 KÜTLE DENKLİĞİ'!L2:L501,"KAPALI") -> 11 | G17: DENETİM DURUMU | H17: ADET
A18: Toplam sevk kg | B18: =SUM('23 2026 SEVKİYAT'!H2:H501) -> 2351 | D18: Kontrol gereken | E18: =COUNTIF('24 2026 KÜTLE DENKLİĞİ'!L2:L501,"KONTROL") -> 0 | G18: Gerçek veri işlendi | H18: =COUNTIF('02 DENETİM KONTROL'!C2:C100,"*İŞLENDİ*") -> 7
A19: Hesaplanan paketli stok kg | B19: =SUM('22 2026 PAKETLEME'!E2:E501)+SUM('22 2026 PAKETLEME'!G2:G501)-SUM('23 2026 SEVKİYAT'!H2:H501) -> 11 | D19: Negatif paketli stok | E19: =COUNTIF('24 2026 KÜTLE DENKLİĞİ'!J2:J501,"<0") -> 0 | G19: Açık aksiyon | H19: =COUNTIF('02 DENETİM KONTROL'!C2:C100,"AÇIK AKSİYON") -> 2
D20: Toplam paketleme bakiyesi kg | E20: =SUMPRODUCT(IFERROR('24 2026 KÜTLE DENKLİĞİ'!H2:H501,0)) -> 0 | G20: Kontrollü belge gerekiyor | H20: =COUNTIF('02 DENETİM KONTROL'!C2:C100,"KONTROLLÜ BELGE GEREKİYOR") -> 8
G21: Revizyon kontrolü | H21: =COUNTIF('02 DENETİM KONTROL'!C2:C100,"REVİZYON KONTROLÜ") -> 4
G23: REV.08 PAKETLEME KAYITLARI DOLU
G24: 2026 üretim satırı | H24: 11
G25: 2026 paketleme tarih satırı | H25: 11
G26: 2026 sevkiyat satırı | H26: 7
G27: 2026 lot bağı satırı | H27: 86
G28: Paketleme tarih kuralı | H28: Üretim tarihinden sonraki gün
G29: 2026 dolu paketleme kaydı | H29: 11

Sheet 01 VERİ ENVANTERİ
A1: Kayıt Grubu | B1: 2025 / 2026 | C1: Sistemdeki Durum | D1: Kontrol Notu
A2: Üretim | B2: 2026 | C2: 11 gerçek üretim kaydı konsolide | D2: 14.01, 17.02 ve 15.04–23.06 kayıtları
A3: Sevkiyat | B3: 2026 | C3: 8 hareket konsolide | D3: File Market 2.880 paket 500 g dahil
A4: Temizlik | B4: 2026 | C4: 9 üretim sonrası kayıt konsolide | D4: 15.04–23.06 lot bağlantılı
A5: Lot İzlenebilirliği | B5: 2026 | C5: 9 ürün lotu × 8 hammadde lotu konsolide | D5: 270415–270623
A6: Paketleme | B6: 2026 | C6: 14.01 ve 17.02 kesin; diğerleri teyit gerektiriyor | D6: Teorik net ürün paketlenmiş ürün kabul edilmedi
A7: 2025 tarihsel dönem | B7: 2025 | C7: Ayrı sayfalarda korunuyor | D7: 1 kg yalnızca tarihsel dönemde
A8: Etiket aksiyonu | B8: 2026 | C8: Ana operasyon verisinden ayrı kontrollü aksiyon | D8: Nihai reçete/alerjen doğrulaması açık
A9: Denetim çapraz taraması | B9: 2025 / 2026 | C9: Belge kontrol matrisi eklendi | D9: Taslak statüsü, 12000 Gauss, proses adımı, koruyucu ifadesi, etiket ve açık kayıtlar işaretlendi
A10: Veri koruma kuralı | B10: TÜM DÖNEM | C10: Gerçek veri silinmeden revizyon | D10: Eksik bilgi varsa açık aksiyon; gerçekleşmemiş faaliyet geçmiş tarihli yapılmış gibi yazılmaz

Sheet 02 DENETİM KONTROL
A1: Klasör | B1: Belge / Kayıt | C1: Durum | D1: Gerçek Veri / Kaynak | E1: Aksiyon | F1: Geçmişe Dönük Uydurma Kayıt?
A2: 01 HACCP | B2: HACCP Planı | C2: REVİZYON KONTROLÜ | D2: Mevcut taslak/çapraz kontrol | E2: 12000 Gauss mıknatıs kontrolü ve proses adımları doğrulanacak | F2: HAYIR
A3: 01 HACCP | B3: Tehlike Analizi / CCP | C3: REVİZYON KONTROLÜ | D3: Mevcut taslak/çapraz kontrol | E3: Fiziksel tehlike ve mıknatıs kontrolü netleştirilecek | F3: HAYIR
A4: 01 HACCP | B4: Alerjen Yönetimi | C4: AÇIK AKSİYON | D4: Savour bileşeninde kereviz kaydı | E4: Nihai etiket/alerjen metni doğrulanacak | F4: HAYIR
A5: 02 Üretim | B5: 2026 Üretim Kayıtları | C5: GERÇEK VERİ İŞLENDİ | D5: 11 üretim kaydı | E5: Ana sistemde korunacak | F5: HAYIR
A6: 02 Üretim | B6: Lot İzlenebilirliği | C6: GERÇEK VERİ İŞLENDİ | D6: 270415–270623 ürün lotları ve 8 hammadde lotu | E6: 14.01 ve 17.02 lot bağı ayrıca mevcut kayıttan korunacak | F6: HAYIR
A7: 02 Üretim | B7: Fire Kayıtları | C7: GERÇEK VERİ İŞLENDİ | D7: Üretim fireleri | E7: Haziran sıcak hava/tepsileme nedenleri korunacak | F7: HAYIR
A8: 02 Üretim | B8: Kütle Denkliği | C8: KISMEN KAPALI | D8: 14.01 ve 17.02 kesin paketleme | E8: Nisan–Haziran gerçek paketleme adetleri olmadan teorik net paketlenmiş sayılmayacak | F8: HAYIR
A9: 03 Kalite | B9: Son Ürün Spesifikasyonu | C9: KONTROLLÜ BELGE GEREKİYOR | D9: 12 ay raf ömrü / -18°C | E9: Nihai revizyon kontrolü | F9: HAYIR
A10: 03 Kalite | B10: Proses Kalite Planı | C10: REVİZYON KONTROLÜ | D10: Mevcut çapraz kontrol bulgusu | E10: Kesme/ürün boyu adımı gerçek prosesle doğrulanacak | F10: HAYIR
A11: 04 Depo | B11: 2025–2026 Hammadde Girişleri | C11: GERÇEK VERİ MEVCUT | D11: Kullanıcı lot ve alım beyanları + faturalar | E11: Ana depo kabul havuzunda konsolide edilecek | F11: HAYIR
A12: 04 Depo | B12: Onaylı Tedarikçi Listesi | C12: GERÇEK VERİ MEVCUT | D12: Satütaş, Değirmenci, Sizin Gıda, Ankara Gıda, Metro, IMCD | E12: Kontrollü listeye bağlanacak | F12: HAYIR
... A28: Etiket | B28: 500 g etiket uygunluk aksiyonu | C28: AÇIK AKSİYON | D28: Yaklaşık 5.000 etiket; reçete/alerjen kontrolü | E28: Yeni baskı öncesi nihai içerik doğrulaması | F28: HAYIR

Sheet 03 REV08 ÇAPRAZ KONTROL
A1: KONTROL | B1: KAYNAK | C1: ANA SİSTEM | D1: SONUÇ | E1: NOT
A2: 2026 Ocak-Şubat üretim | B2: FR-GV-001: 2 satır | C2: 21 2026 ÜRETİM: 2 satır | D2: EŞLEŞTİ | E2: 14.01 ve 17.02 geri eklendi
A3: 2026 Nisan-Haziran üretim | B3: Gerçek kayıt: 9 satır | C3: 21 2026 ÜRETİM: 9 satır | D3: EŞLEŞTİ | E3: 15.04–23.06
A4: 2026 paketleme kesin kayıt | B4: FR-GV-001: 2 satır | C4: 22 2026 PAKETLEME: 2 kesin satır | D4: EŞLEŞTİ | E4: Ocak-Şubat
A5: 2026 sevkiyat Ocak-Mart | B5: FR-GV-001: 4 satır | C5: 23 2026 SEVKİYAT: 4 satır | D5: EŞLEŞTİ | E5: 1 sevk tarihi açık
A6: 2026 sevkiyat Mayıs-Haziran | B6: Gerçek kayıt: 3 satır | C6: 23 2026 SEVKİYAT: 3 satır | D6: EŞLEŞTİ | E6: File/Samsun/Şehzade
A7: File Market paket | B7: 2.880 paket / 1.440 kg | C7: 2.880 paket / 1.440 kg | D7: EŞLEŞTİ | E7: 500 g
A8: Samsun Terme | B8: 114 kg / paket adedi teyitsiz | C8: 114 kg / paket adedi TEYİT | D8: EŞLEŞTİ | E8: 45,6 paket hatası kaldırıldı
A9: 2026 lot bağı | B9: Ocak-Şubat + Nisan-Haziran | C9: Tüm 11 üretim tarihi bağlı | D9: EŞLEŞTİ | E9: Lot satırları birleştirildi
A10: 2026 üretim/paketleme tarih kuralı | B10: Her üretim +1 gün | C10: 11 üretim / 11 paketleme tarihi | D10: EŞLEŞTİ | E10: Gündüz paketleme, akşam yeni üretim yapılabilir; kayıtlar üretim lotuna göre bağlı
A11: Paket adedi veri kuralı | B11: Kesin kayıt varsa doldur | C11: Teyitsiz adet boş | D11: EŞLEŞTİ | E11: Paketleme tarihi oluşturuldu; paket adetleri uydurulmadı
A12: 2026 paketleme ambalaj kaydı | B12: Önceki kayıtlarla dolduruldu | C12: Ocak-Şubat karma; Nisan-Haziran 500 g | D12: EŞLEŞTİ | E12: Üretim kayıtlarındaki ambalaj bilgisi paketleme sayfasına aktarıldı; boş teyit satırları kaldırıldı.

Sheet 04 TANIMLAR
A1: Hammadde | B1: Varsayılan Tedarikçi | C1: Birim | E1: Ambalaj | G1: Durum | I1: Temizlik Durumu
A2: Patates unu | B2: Satütaş | C2: kg | E2: 500 g | G2: KABUL | I2: Tamamlandı
A3: Mısır nişastası | B3: Değirmenci Gıda | C3: kg | E3: 2,5 kg | G3: ŞARTLI KABUL | I3: Açık
A4: Tat mısır unu | B4: Sizin Gıda | C4: kg | G4: RED
A5: Savour tavuk çeşnisi | B5: Ankara Gıda | C5: kg
A6: Sarımsak tozu | B6: Sizin Gıda | C6: kg
A7: Karabiber | B7: Metro Market | C7: kg
A8: Tuz | B8: Sizin Gıda | C8: kg
A9: BENECEL A4M | B9: IMCD Türkiye | C9: kg

Sheet 05 REV11 FİNAL TARAMA
A1: Kontrol | B1: Sonuç | C1: Açıklama
A2: Formül referans hatası | B2: UYGUN | C2: 0 hata
A3: Eski sayfa adına bağlı formül | B3: UYGUN | C3: 0 eski referans
A4: 502+ sabit veri bloğu | B4: UYGUN | C4: Mükerrer alt veri bloğu yok
A5: Birebir aynı satır tekrarı | B5: UYGUN | C5: 0 satır; boş/formül şablonları hariç
A6: Paketleme ertesi gün kontrolü | B6: UYGUN | C6: 0 tarih sapması
A7: Sevkiyat aynı kimlikte tekrar | B7: UYGUN | C7: {}
A8: 2025 dönem yapısı | B8: KORUNDU | C8: Kapanmış tarihsel kayıt sekmeleri değiştirilmedi
A9: 2026 operasyon sırası | B9: UYGUN | C9: Depo Kabul → Üretim → Paketleme → Sevkiyat → Kütle Denkliği → Lot Bağı → Temizlik

Sheet 06 LOT LİSTELERİ
A1: Patates unu | B1: Mısır nişastası | C1: Tat mısır unu | D1: Savour tavuk çeşnisi | E1: Sarımsak tozu | F1: Karabiber | G1: Tuz | H1: BENECEL A4M
A2: 251011 | B2: 57108774 | C2: 9222 | D2: 01.09.EY | E2: 040126-141 | F2: 170126-678 | G2: 20423 | H2: 2743063
A3: 251212 | B3: 58138875 | C3: 8825 | E3: 170226-157 | F3: 161125-567 | G3: 20425
C4: 9226 | F4: 070426-693

Sheet 10 2025 ÜRETİM
A1: Üretim Tarihi | B1: Parti | C1: kg/Parti | D1: Teorik kg | E1: Üretim Firesi kg | F1: Net Mamul kg | G1: Paketleme
A2: 18.09.2025 | B2: 13 | C2: 20.412 | D2: 265.356 | E2: 4 | F2: 261.356 | G2: 500 g
A3: 19.09.2025 | B3: 13 | C3: 20.412 | D3: 265.356 | E3: 5 | F3: 260.356 | G3: 500 g
A4: 20.09.2025 | B4: 13 | C4: 20.412 | D4: 265.356 | E4: 3 | F4: 262.356 | G4: 500 g
A5: 21.09.2025 | B5: 13 | C5: 20.412 | D5: 265.356 | E5: 4 | F5: 261.356 | G5: 500 g
A6: 22.09.2025 | B6: 13 | C6: 20.412 | D6: 265.356 | E6: 4 | F6: 261.356 | G6: 500 g
A7: 23.09.2025 | B7: 9 | C7: 20.412 | D7: 183.708 | E7: 3 | F7: 180.708 | G7: 500 g
A8: 20.10.2025 | B8: 12 | C8: 20.412 | D8: 244.944 | E8: 4 | F8: 240.944 | G8: 1 kg — TARİHSEL
A9: 23.12.2025 | B9: 12 | C9: 20.412 | D9: 244.944 | E9: 5 | F9: 239.944 | G9: 1 kg + 2,5 kg — TARİHSEL

Sheet 11 2025 PAKETLEME
A1: Üretim Bağı | B1: 500 g Paket | C1: 500 g kg | D1: 1 kg Paket TARİHSEL | E1: 1 kg kg | F1: 2,5 kg Paket | G1: 2,5 kg kg | H1: Paketleme Firesi kg
A2: 18–23.09.2025 | B2: 2974 | C2: 1487 | D2: 0 | E2: 0 | F2: 0 | G2: 0 | H2: 0.488
A3: 20.10.2025 | B3: 0 | C3: 0 | D3: 240 | E3: 240 | F3: 0 | G3: 0 | H3: 0.944
A4: 23.12.2025 | B4: 0 | C4: 0 | D4: 100 | E4: 100 | F4: 55 | G4: 137.5 | H4: 2.444

Sheet 12 2025 SEVKİYAT
A1: Sevk Tarihi | B1: Alıcı | C1: Lojistik | D1: Plaka | E1: Üretim Bağı | F1: Ambalaj | G1: Paket | H1: kg
A2: 01.10.2025 | B2: File Market | C2: Narlog Lojistik | D2: 34 AAB 37 | E2: 18–23.09.2025 | F2: 500 g | G2: 2880 | H2: 1440
A3: 22.10.2025 | B3: Arca Burger | C3: PolarXP | D3: BİLDİRİLMİYOR | E3: 20.10.2025 | F3: 1 kg TARİHSEL | G3: 48 | H3: 48
A4: 03.12.2025 | B4: Carnaval | C4: PolarXP | D4: BİLDİRİLMİYOR | E4: 20.10.2025 | F4: 1 kg TARİHSEL | G4: 80 | H4: 80
A5: 16.12.2025 | B5: Senem Değerli | C5: PolarXP | D5: BİLDİRİLMİYOR | E5: 20.10.2025 | F5: 1 kg TARİHSEL | G5: 80 | H5: 80
A6: 25.12.2025 | B6: Carnaval | C6: PolarXP | D6: BİLDİRİLMİYOR | E6: 23.12.2025 | F6: 1 kg TARİHSEL | G6: 80 | H6: 80

Sheet 90 2025 YIL ÖZETİ
A1: 2025 TARİHSEL YIL ÖZETİ
A3: Toplam üretim günü | B3: =COUNT('10 2025 ÜRETİM'!A2:A100) -> 0
A4: Toplam parti | B4: =SUM('10 2025 ÜRETİM'!B2:B100) -> 98
A5: Teorik kg | B5: =SUM('10 2025 ÜRETİM'!D2:D100) -> 2000.376
A6: Üretim firesi kg | B6: =SUM('10 2025 ÜRETİM'!E2:E100) -> 32
A7: Net mamul kg | B7: =SUM('10 2025 ÜRETİM'!F2:F100) -> 1968.376
A8: 500 g paket | B8: =SUM('11 2025 PAKETLEME'!B2:B100) -> 2974
A9: 1 kg paket — tarihsel | B9: =SUM('11 2025 PAKETLEME'!D2:D100) -> 340
A10: 2,5 kg paket | B10: =SUM('11 2025 PAKETLEME'!F2:F100) -> 55
A11: Doğrulanmış sevk kg | B11: =SUM('12 2025 SEVKİYAT'!H2:H100) -> 1728

Sheet 20 2026 DEPO KABUL
A1: Giriş Tarihi | B1: Hammadde Seç | C1: Tedarikçi Otomatik | D1: Miktar | E1: Birim Otomatik | F1: Lot No | G1: ÜRT | H1: SKT | I1: Kabul Durumu | J1: Açıklama | V1: ⌂ ANA SAYFA
A2: 02.01.2026 | B2: Patates unu | C2: Satütaş | F2: 251011 | G2: 02.01.2026 | I2: KABUL | V2: → ÜRETİM
A3: 02.01.2026 | B3: Mısır nişastası | C3: Değirmenci Gıda | F3: 57108774 | G3: 05.01.2026 | H3: 05.01.2028 | I3: KABUL | V3: → LOT BAĞI
A4: 02.01.2026 | B4: BENECEL A4M | C4: IMCD Türkiye | F4: 2743063 | G4: 08.01.2026 | H4: 08.01.2028 | I4: KABUL
A5: 02.01.2026 | B5: Tuz | C5: Sizin Gıda | F5: 20423 | G5: 16.11.2025 | H5: 16.11.2029 | I5: KABUL
A6: 02.01.2026 | B6: Tat mısır unu | C6: Sizin Gıda | F6: 9222 | G6: 13.01.2026 | H6: 13.01.2027 | I6: KABUL | J6: Kronoloji doğrulama
A7: 02.01.2026 | B7: Karabiber | C7: Metro Market | F7: 170126-678 | G7: 17.01.2026 | H7: 17.01.2028 | I7: KABUL | J7: Kronoloji doğrulama
A8: 02.01.2026 | B8: Sarımsak tozu | C8: Sizin Gıda | F8: 040126-141 | G8: 04.01.2026 | H8: 04.01.2028 | I8: KABUL
A9: 02.02.2026 | B9: Tat mısır unu | C9: Sizin Gıda | F9: 8825 | G9: 05.12.2025 | H9: 05.12.2026 | I9: KABUL
A10: 02.02.2026 | B10: Karabiber | C10: Metro Market | F10: 161125-567 | G10: 16.11.2025 | H10: 16.11.2027 | I10: KABUL
B11: Patates unu | C11: Satütaş | E11: =IF(B11="","",IFERROR(VLOOKUP(B11,'04 TANIMLAR'!$A$2:$C$9,3,FALSE()),"")) -> kg | F11: 251212 | G11: 12.12.2025 | H11: 12.12.2026 | I11: TEYİT | J11: TARİHSEL LOT KAYDI — giriş/alım tarihi satın alma kaydıyla eşleştirilecek
B12: Mısır nişastası | C12: Değirmenci Gıda | E12: =IF(B12="","",IFERROR(VLOOKUP(B12,'04 TANIMLAR'!$A$2:$C$9,3,FALSE()),"")) -> kg | F12: 58138875 | G12: 09.09.2025 | H12: 09.09.2027 | I12: TEYİT | J12: TARİHSEL LOT KAYDI — giriş/alım tarihi satın alma kaydıyla eşleştirilecek
B13: Tat mısır unu | C13: Sizin Gıda | E13: =IF(B13="","",IFERROR(VLOOKUP(B13,'04 TANIMLAR'!$A$2:$C$9,3,FALSE()),"")) -> kg | F13: 9226 | G13: 20.02.2026 | H13: 20.02.2027 | I13: TEYİT | J13: TARİHSEL LOT KAYDI — giriş/alım tarihi satın alma kaydıyla eşleştirilecek
B14: Savour tavuk çeşnisi | C14: Ankara Gıda | E14: =IF(B14="","",IFERROR(VLOOKUP(B14,'04 TANIMLAR'!$A$2:$C$9,3,FALSE()),"")) -> kg | F14: 01.09.EY | I14: TEYİT | J14: TARİHSEL LOT KAYDI — giriş/alım tarihi satın alma kaydıyla eşleştirilecek
B15: Sarımsak tozu | C15: Sizin Gıda | E15: =IF(B15="","",IFERROR(VLOOKUP(B15,'04 TANIMLAR'!$A$2:$C$9,3,FALSE()),"")) -> kg | F15: 170226-157 | G15: 17.02.2026 | H15: 17.02.2028 | I15: TEYİT | J15: TARİHSEL LOT KAYDI — giriş/alım tarihi satın alma kaydıyla eşleştirilecek
B16: Karabiber | C16: Metro Market | E16: =IF(B16="","",IFERROR(VLOOKUP(B16,'04 TANIMLAR'!$A$2:$C$9,3,FALSE()),"")) -> kg | F16: 070426-693 | G16: 07.04.2026 | H16: 07.04.2028 | I16: TEYİT | J16: TARİHSEL LOT KAYDI — giriş/alım tarihi satın alma kaydıyla eşleştirilecek
B17: Tuz | C17: Sizin Gıda | E17: =IF(B17="","",IFERROR(VLOOKUP(B17,'04 TANIMLAR'!$A$2:$C$9,3,FALSE()),"")) -> kg | F17: 20425 | G17: 23.07.2025 | H17: 23.07.2026 | I17: TEYİT | J17: TARİHSEL LOT KAYDI — giriş/alım tarihi satın alma kaydıyla eşleştirilecek
C18: =IF(B18="","",IFERROR(VLOOKUP(B18,'04 TANIMLAR'!$A$2:$C$9,2,FALSE()),"")) | E18: =IF(B18="","",IFERROR(VLOOKUP(B18,'04 TANIMLAR'!$A$2:$C$9,3,FALSE()),""))
C19: =IF(B19="","",IFERROR(VLOOKUP(B19,'04 TANIMLAR'!$A$2:$C$9,2,FALSE()),"")) | E19: =IF(B19="","",IFERROR(VLOOKUP(B19,'04 TANIMLAR'!$A$2:$C$9,3,FALSE()),""))
C20: =IF(B20="","",IFERROR(VLOOKUP(B20,'04 TANIMLAR'!$A$2:$C$9,2,FALSE()),"")) | E20: =IF(B20="","",IFERROR(VLOOKUP(B20,'04 TANIMLAR'!$A$2:$C$9,3,FALSE()),""))
C21: =IF(B21="","",IFERROR(VLOOKUP(B21,'04 TANIMLAR'!$A$2:$C$9,2,FALSE()),"")) | E21: =IF(B21="","",IFERROR(VLOOKUP(B21,'04 TANIMLAR'!$A$2:$C$9,3,FALSE()),""))
C22: =IF(B22="","",IFERROR(VLOOKUP(B22,'04 TANIMLAR'!$A$2:$C$9,2,FALSE()),"")) | E22: =IF(B22="","",IFERROR(VLOOKUP(B22,'04 TANIMLAR'!$A$2:$C$9,3,FALSE()),""))
C23: =IF(B23="","",IFERROR(VLOOKUP(B23,'04 TANIMLAR'!$A$2:$C$9,2,FALSE()),"")) | E23: =IF(B23="","",IFERROR(VLOOKUP(B23,'04 TANIMLAR'!$A$2:$C$9,3,FALSE()),""))
C24: =IF(B24="","",IFERROR(VLOOKUP(B24,'04 TANIMLAR'!$A$2:$C$9,2,FALSE()),"")) | E24: =IF(B24="","",IFERROR(VLOOKUP(B24,'04 TANIMLAR'!$A$2:$C$9,3,FALSE()),""))
C25: =IF(B25="","",IFERROR(VLOOKUP(B25,'04 TANIMLAR'!$A$2:$C$9,2,FALSE()),"")) | E25: =IF(B25="","",IFERROR(VLOOKUP(B25,'04 TANIMLAR'!$A$2:$C$9,3,FALSE()),""))
C26: =IF(B26="","",IFERROR(VLOOKUP(B26,'04 TANIMLAR'!$A$2:$C$9,2,FALSE()),"")) | E26: =IF(B26="","",IFERROR(VLOOKUP(B26,'04 TANIMLAR'!$A$2:$C$9,3,FALSE()),""))
C27: =IF(B27="","",IFERROR(VLOOKUP(B27,'04 TANIMLAR'!$A$2:$C$9,2,FALSE()),"")) | E27: =IF(B27="","",IFERROR(VLOOKUP(B27,'04 TANIMLAR'!$A$2:$C$9,3,FALSE()),""))
C28: =IF(B28="","",IFERROR(VLOOKUP(B28,'04 TANIMLAR'!$A$2:$C$9,2,FALSE()),"")) | E28: =IF(B28="","",IFERROR(VLOOKUP(B28,'04 TANIMLAR'!$A$2:$C$9,3,FALSE()),""))
C29: =IF(B29="","",IFERROR(VLOOKUP(B29,'04 TANIMLAR'!$A$2:$C$9,2,FALSE()),"")) | E29: =IF(B29="","",IFERROR(VLOOKUP(B29,'04 TANIMLAR'!$A$2:$C$9,3,FALSE()),""))
... C501: =IF(B501="","",IFERROR(VLOOKUP(B501,'04 TANIMLAR'!$A$2:$C$9,2,FALSE()),"")) | E501: =IF(B501="","",IFERROR(VLOOKUP(B501,'04 TANIMLAR'!$A$2:$C$9,3,FALSE()),""))

Sheet 21 2026 ÜRETİM
A1: Üretim Tarihi | B1: Parti | C1: kg/Parti | D1: Teorik kg | E1: Üretim Firesi kg | F1: Net Mamul kg | G1: Üretim Lot No | H1: Açıklama | V1: ⌂ ANA SAYFA
A2: 14.01.2026 | B2: 12 | C2: 20.412 | D2: 244.944 | E2: 4 | F2: 240.944 | G2: 270114 | H2: Ocak geçmiş kayıt; FR-GV-001 ile doğrulandı | V2: → ÜRETİM
A3: 17.02.2026 | B3: 11 | C3: 20.412 | D3: 224.532 | E3: 3 | F3: 221.532 | G3: 270217 | H3: Şubat geçmiş kayıt; FR-GV-001 ile doğrulandı | V3: → LOT BAĞI
A4: 15.04.2026 | B4: 13 | C4: 20.412 | D4: 265.356 | E4: 5 | F4: 260 | G4: 270415 | H4: Kullanıcı beyanı: 260 kg ürün
A5: 27.04.2026 | B5: 13 | C5: 20.412 | D5: 265.356 | E5: 4 | F5: 261.356 | G5: 270427 | H5: Hesaplanan net
A6: 04.05.2026 | B6: 13 | C6: 20.412 | D6: 265.356 | E6: 6 | F6: 259.356 | G6: 270504 | H6: Hesaplanan net
A7: 05.05.2026 | B7: 13 | C7: 20.412 | D7: 265.356 | E7: 5 | F7: 260.356 | G7: 270505 | H7: Hesaplanan net
A8: 07.05.2026 | B8: 13 | C8: 20.412 | D8: 265.356 | E8: 6 | F8: 259.356 | G8: 270507 | H8: Hesaplanan net
A9: 12.05.2026 | B9: 13 | C9: 20.412 | D9: 265.356 | E9: 5 | F9: 260.356 | G9: 270512 | H9: Hesaplanan net
A10: 15.06.2026 | B10: 6 | C10: 20.412 | D10: 122.472 | E10: 40 | F10: 82.472 | G10: 270615 | H10: Sıcak hava / tepsileme makinesi ürünü tepsiye alamadı
A11: 17.06.2026 | B11: 7 | C11: 20.412 | D11: 142.884 | E11: 15 | F11: 127.884 | G11: 270617 | H11: Sıcak hava / tepsileme kaynaklı fire
A12: 23.06.2026 | B12: 7 | C12: 20.412 | D12: 142.884 | E12: 10 | F12: 132.884 | G12: 270623 | H12: Sıcak hava / tepsileme kaynaklı fire
C13: =IF(B13="","",20.412) | D13: =IF(B13="","",B13*C13) | F13: =IF(D13="","",D13-IF(E13="",0,E13)) | G13: =IF(A13="","","27"&MID(A13,4,2)&LEFT(A13,2))
C14: =IF(B14="","",20.412) | D14: =IF(B14="","",B14*C14) | F14: =IF(D14="","",D14-IF(E14="",0,E14)) | G14: =IF(A14="","","27"&MID(A14,4,2)&LEFT(A14,2))
C15: =IF(B15="","",20.412) | D15: =IF(B15="","",B15*C15) | F15: =IF(D15="","",D15-IF(E15="",0,E15)) | G15: =IF(A15="","","27"&MID(A15,4,2)&LEFT(A15,2))
C16: =IF(B16="","",20.412) | D16: =IF(B16="","",B16*C16) | F16: =IF(D16="","",D16-IF(E16="",0,E16)) | G16: =IF(A16="","","27"&MID(A16,4,2)&LEFT(A16,2))
C17: =IF(B17="","",20.412) | D17: =IF(B17="","",B17*C17) | F17: =IF(D17="","",D17-IF(E17="",0,E17)) | G17: =IF(A17="","","27"&MID(A17,4,2)&LEFT(A17,2))
C18: =IF(B18="","",20.412) | D18: =IF(B18="","",B18*C18) | F18: =IF(D18="","",D18-IF(E18="",0,E18)) | G18: =IF(A18="","","27"&MID(A18,4,2)&LEFT(A18,2))
C19: =IF(B19="","",20.412) | D19: =IF(B19="","",B19*C19) | F19: =IF(D19="","",D19-IF(E19="",0,E19)) | G19: =IF(A19="","","27"&MID(A19,4,2)&LEFT(A19,2))
C20: =IF(B20="","",20.412) | D20: =IF(B20="","",B20*C20) | F20: =IF(D20="","",D20-IF(E20="",0,E20)) | G20: =IF(A20="","","27"&MID(A20,4,2)&LEFT(A20,2))
C21: =IF(B21="","",20.412) | D21: =IF(B21="","",B21*C21) | F21: =IF(D21="","",D21-IF(E21="",0,E21)) | G21: =IF(A21="","","27"&MID(A21,4,2)&LEFT(A21,2))
C22: =IF(B22="","",20.412) | D22: =IF(B22="","",B22*C22) | F22: =IF(D22="","",D22-IF(E22="",0,E22)) | G22: =IF(A22="","","27"&MID(A22,4,2)&LEFT(A22,2))
C23: =IF(B23="","",20.412) | D23: =IF(B23="","",B23*C23) | F23: =IF(D23="","",D23-IF(E23="",0,E23)) | G23: =IF(A23="","","27"&MID(A23,4,2)&LEFT(A23,2))
C24: =IF(B24="","",20.412) | D24: =IF(B24="","",B24*C24) | F24: =IF(D24="","",D24-IF(E24="",0,E24)) | G24: =IF(A24="","","27"&MID(A24,4,2)&LEFT(A24,2))
... C501: =IF(B501="","",20.412) | D501: =IF(B501="","",B501*C501) | F501: =IF(D501="","",D501-IF(E501="",0,E501)) | G501: =IF(A501="","","27"&MID(A501,4,2)&LEFT(A501,2))

Sheet 22 2026 PAKETLEME
A1: Paketleme Tarihi | B1: Üretim Bağı | C1: Net Mamul kg | D1: 500 g Paket | E1: 500 g kg | F1: 2,5 kg Paket | G1: 2,5 kg kg | H1: Paketleme Firesi kg | I1: Bakiye kg | J1: Sonuç | K1: Açıklama | V1: ⌂ ANA SAYFA
A2: 15.01.2026 | B2: 14.01.2026 | C2: 240.944 | D2: 0 | E2: 0 | F2: 96 | G2: 240 | H2: 0.944 | I2: =C2-E2-G2-H2 -> -1.1546319e-14 | J2: =IF(ABS(I2)<0.001,"KAPALI","KONTROL") -> KAPALI | K2: 100 kg ALEK + 140 kg festival/fuar | V2: → ÜRETİM
A3: 18.02.2026 | B3: 17.02.2026 | C3: 221.532 | D3: 352 | E3: 176 | F3: 18 | G3: 45 | H3: 0.532 | I3: =C3-E3-G3-H3 -> 1.0658141e-14 | J3: =IF(ABS(I3)<0.001,"KAPALI","KONTROL") -> KAPALI | K3: 11 koli 500 g; kalan 2,5 kg | V3: → LOT BAĞI
A4: 16.04.2026 | B4: 15.04.2026 | C4: 260 | D4: 520 | E4: 260 | F4: 0 | G4: 0 | H4: 0 | I4: =C4-E4-G4-H4 -> 0 | J4: =IF(ABS(I4)<0.001,"KAPALI","KONTROL") -> KAPALI
A5: 28.04.2026 | B5: 27.04.2026 | C5: 261.356 | D5: 522 | E5: 261 | F5: 0 | G5: 0 | H5: 0.356 | I5: =C5-E5-G5-H5 -> -5.4400928e-15 | J5: =IF(ABS(I5)<0.001,"KAPALI","KONTROL") -> KAPALI
A6: 05.05.2026 | B6: 04.05.2026 | C6: 259.356 | D6: 518 | E6: 259 | F6: 0 | G6: 0 | H6: 0.356 | I6: =C6-E6-G6-H6 -> -5.4400928e-15 | J6: =IF(ABS(I6)<0.001,"KAPALI","KONTROL") -> KAPALI
A7: 06.05.2026 | B7: 05.05.2026 | C7: 260.356 | D7: 520 | E7: 260 | F7: 0 | G7: 0 | H7: 0.356 | I7: =C7-E7-G7-H7 -> -5.4400928e-15 | J7: =IF(ABS(I7)<0.001,"KAPALI","KONTROL") -> KAPALI
A8: 08.05.2026 | B8: 07.05.2026 | C8: 259.356 | D8: 518 | E8: 259 | F8: 0 | G8: 0 | H8: 0.356 | I8: =C8-E8-G8-H8 -> -5.4400928e-15 | J8: =IF(ABS(I8)<0.001,"KAPALI","KONTROL") -> KAPALI
A9: 13.05.2026 | B9: 12.05.2026 | C9: 260.356 | D9: 520 | E9: 260 | F9: 0 | G9: 0 | H9: 0.356 | I9: =C9-E9-G9-H9 -> -5.4400928e-15 | J9: =IF(ABS(I9)<0.001,"KAPALI","KONTROL") -> KAPALI
A10: 16.06.2026 | B10: 15.06.2026 | C10: 82.472 | D10: 164 | E10: 82 | F10: 0 | G10: 0 | H10: 0.472 | I10: =C10-E10-G10-H10 -> -5.7731597e-15 | J10: =IF(ABS(I10)<0.001,"KAPALI","KONTROL") -> KAPALI
A11: 18.06.2026 | B11: 17.06.2026 | C11: 127.884 | D11: 255 | E11: 127.5 | F11: 0 | G11: 0 | H11: 0.384 | I11: =C11-E11-G11-H11 -> 0 | J11: =IF(ABS(I11)<0.001,"KAPALI","KONTROL") -> KAPALI
A12: 24.06.2026 | B12: 23.06.2026 | C12: 132.884 | D12: 265 | E12: 132.5 | F12: 0 | G12: 0 | H12: 0.384 | I12: =C12-E12-G12-H12 -> -1.3877788e-14 | J12: =IF(ABS(I12)<0.001,"KAPALI","KONTROL") -> KAPALI
A13: =IF(B13="","",IFERROR(DATE(RIGHT(B13,4),MID(B13,4,2),LEFT(B13,2))+1,"")) | C13: =IF(B13="","",IFERROR(INDEX('21 2026 ÜRETİM'!$F$2:$F$501,MATCH(B13,'21 2026 ÜRETİM'!$A$2:$A$501,0)),"")) | E13: =IF(D13="","",D13*0.5) | G13: =IF(F13="","",F13*2.5) | I13: =IF(C13="","",C13-E13-G13-IF(H13="",0,H13)) | J13: =IF(C13="","",IF(ABS(I13)<0.001,"KAPALI","KONTROL"))
A14: =IF(B14="","",IFERROR(DATE(RIGHT(B14,4),MID(B14,4,2),LEFT(B14,2))+1,"")) | C14: =IF(B14="","",IFERROR(INDEX('21 2026 ÜRETİM'!$F$2:$F$501,MATCH(B14,'21 2026 ÜRETİM'!$A$2:$A$501,0)),"")) | E14: =IF(D14="","",D14*0.5) | G14: =IF(F14="","",F14*2.5) | I14: =IF(C14="","",C14-E14-G14-IF(H14="",0,H14)) | J14: =IF(C14="","",IF(ABS(I14)<0.001,"KAPALI","KONTROL"))
A15: =IF(B15="","",IFERROR(DATE(RIGHT(B15,4),MID(B15,4,2),LEFT(B15,2))+1,"")) | C15: =IF(B15="","",IFERROR(INDEX('21 2026 ÜRETİM'!$F$2:$F$501,MATCH(B15,'21 2026 ÜRETİM'!$A$2:$A$501,0)),"")) | E15: =IF(D15="","",D15*0.5) | G15: =IF(F15="","",F15*2.5) | I15: =IF(C15="","",C15-E15-G15-IF(H15="",0,H15)) | J15: =IF(C15="","",IF(ABS(I15)<0.001,"KAPALI","KONTROL"))
A16: =IF(B16="","",IFERROR(DATE(RIGHT(B16,4),MID(B16,4,2),LEFT(B16,2))+1,"")) | C16: =IF(B16="","",IFERROR(INDEX('21 2026 ÜRETİM'!$F$2:$F$501,MATCH(B16,'21 2026 ÜRETİM'!$A$2:$A$501,0)),"")) | E16: =IF(D16="","",D16*0.5) | G16: =IF(F16="","",F16*2.5) | I16: =IF(C16="","",C16-E16-G16-IF(H16="",0,H16)) | J16: =IF(C16="","",IF(ABS(I16)<0.001,"KAPALI","KONTROL"))
A17: =IF(B17="","",IFERROR(DATE(RIGHT(B17,4),MID(B17,4,2),LEFT(B17,2))+1,"")) | C17: =IF(B17="","",IFERROR(INDEX('21 2026 ÜRETİM'!$F$2:$F$501,MATCH(B17,'21 2026 ÜRETİM'!$A$2:$A$501,0)),"")) | E17: =IF(D17="","",D17*0.5) | G17: =IF(F17="","",F17*2.5) | I17: =IF(C17="","",C17-E17-G17-IF(H17="",0,H17)) | J17: =IF(C17="","",IF(ABS(I17)<0.001,"KAPALI","KONTROL"))
A18: =IF(B18="","",IFERROR(DATE(RIGHT(B18,4),MID(B18,4,2),LEFT(B18,2))+1,"")) | C18: =IF(B18="","",IFERROR(INDEX('21 2026 ÜRETİM'!$F$2:$F$501,MATCH(B18,'21 2026 ÜRETİM'!$A$2:$A$501,0)),"")) | E18: =IF(D18="","",D18*0.5) | G18: =IF(F18="","",F18*2.5) | I18: =IF(C18="","",C18-E18-G18-IF(H18="",0,H18)) | J18: =IF(C18="","",IF(ABS(I18)<0.001,"KAPALI","KONTROL"))
A19: =IF(B19="","",IFERROR(DATE(RIGHT(B19,4),MID(B19,4,2),LEFT(B19,2))+1,"")) | C19: =IF(B19="","",IFERROR(INDEX('21 2026 ÜRETİM'!$F$2:$F$501,MATCH(B19,'21 2026 ÜRETİM'!$A$2:$A$501,0)),"")) | E19: =IF(D19="","",D19*0.5) | G19: =IF(F19="","",F19*2.5) | I19: =IF(C19="","",C19-E19-G19-IF(H19="",0,H19)) | J19: =IF(C19="","",IF(ABS(I19)<0.001,"KAPALI","KONTROL"))
A20: =IF(B20="","",IFERROR(DATE(RIGHT(B20,4),MID(B20,4,2),LEFT(B20,2))+1,"")) | C20: =IF(B20="","",IFERROR(INDEX('21 2026 ÜRETİM'!$F$2:$F$501,MATCH(B20,'21 2026 ÜRETİM'!$A$2:$A$501,0)),"")) | E20: =IF(D20="","",D20*0.5) | G20: =IF(F20="","",F20*2.5) | I20: =IF(C20="","",C20-E20-G20-IF(H20="",0,H20)) | J20: =IF(C20="","",IF(ABS(I20)<0.001,"KAPALI","KONTROL"))
A21: =IF(B21="","",IFERROR(DATE(RIGHT(B21,4),MID(B21,4,2),LEFT(B21,2))+1,"")) | C21: =IF(B21="","",IFERROR(INDEX('21 2026 ÜRETİM'!$F$2:$F$501,MATCH(B21,'21 2026 ÜRETİM'!$A$2:$A$501,0)),"")) | E21: =IF(D21="","",D21*0.5) | G21: =IF(F21="","",F21*2.5) | I21: =IF(C21="","",C21-E21-G21-IF(H21="",0,H21)) | J21: =IF(C21="","",IF(ABS(I21)<0.001,"KAPALI","KONTROL"))
A22: =IF(B22="","",IFERROR(DATE(RIGHT(B22,4),MID(B22,4,2),LEFT(B22,2))+1,"")) | C22: =IF(B22="","",IFERROR(INDEX('21 2026 ÜRETİM'!$F$2:$F$501,MATCH(B22,'21 2026 ÜRETİM'!$A$2:$A$501,0)),"")) | E22: =IF(D22="","",D22*0.5) | G22: =IF(F22="","",F22*2.5) | I22: =IF(C22="","",C22-E22-G22-IF(H22="",0,H22)) | J22: =IF(C22="","",IF(ABS(I22)<0.001,"KAPALI","KONTROL"))
A23: =IF(B23="","",IFERROR(DATE(RIGHT(B23,4),MID(B23,4,2),LEFT(B23,2))+1,"")) | C23: =IF(B23="","",IFERROR(INDEX('21 2026 ÜRETİM'!$F$2:$F$501,MATCH(B23,'21 2026 ÜRETİM'!$A$2:$A$501,0)),"")) | E23: =IF(D23="","",D23*0.5) | G23: =IF(F23="","",F23*2.5) | I23: =IF(C23="","",C23-E23-G23-IF(H23="",0,H23)) | J23: =IF(C23="","",IF(ABS(I23)<0.001,"KAPALI","KONTROL"))
A24: =IF(B24="","",IFERROR(DATE(RIGHT(B24,4),MID(B24,4,2),LEFT(B24,2))+1,"")) | C24: =IF(B24="","",IFERROR(INDEX('21 2026 ÜRETİM'!$F$2:$F$501,MATCH(B24,'21 2026 ÜRETİM'!$A$2:$A$501,0)),"")) | E24: =IF(D24="","",D24*0.5) | G24: =IF(F24="","",F24*2.5) | I24: =IF(C24="","",C24-E24-G24-IF(H24="",0,H24)) | J24: =IF(C24="","",IF(ABS(I24)<0.001,"KAPALI","KONTROL"))
... A501: =IF(B501="","",IFERROR(DATE(RIGHT(B501,4),MID(B501,4,2),LEFT(B501,2))+1,"")) | C501: =IF(B501="","",IFERROR(INDEX('21 2026 ÜRETİM'!$F$2:$F$501,MATCH(B501,'21 2026 ÜRETİM'!$A$2:$A$501,0)),"")) | E501: =IF(D501="","",D501*0.5) | G501: =IF(F501="","",F501*2.5) | I501: =IF(C501="","",C501-E501-G501-IF(H501="",0,H501)) | J501: =IF(C501="","",IF(ABS(I501)<0.001,"KAPALI","KONTROL"))

Sheet 23 2026 SEVKİYAT
A1: Sevk Tarihi | B1: Alıcı / Hedef | C1: Lojistik | D1: Plaka | E1: Üretim Bağı | F1: Ambalaj | G1: Paket | H1: kg | I1: Not | V1: ⌂ ANA SAYFA
A2: 16.01.2026 | B2: Malatya ALEK Gıda | C2: Kendi / bildirilen araç | D2: 34 AU 125 | E2: 14.01.2026 | F2: 2,5 kg | G2: 40 | H2: 100 | I2: Gerçek kayıt | V2: → ÜRETİM
B3: Festival / Fuar | E3: 14.01.2026 | F3: 2,5 kg | G3: 56 | H3: 140 | I3: Sevk tarihi kesin kanıtı ayrıca kontrol | V3: → LOT BAĞI
A4: 18.02.2026 | B4: Şehzade Market | C4: Kendi araç | D4: 77 AAG 036 | E4: 17.02.2026 | F4: 500 g | G4: 128 | H4: 64 | I4: 4 koli × 32
A5: 25.02.2026 | B5: Fuar aracı | C5: Kendi araç | D5: 77 AAG 036 | E5: 17.02.2026 | F5: 2,5 kg | G5: 18 | H5: 45 | I5: Gerçek kayıt
A6: 27.03.2026 | B6: Şehzade Market | C6: Kendi araç | D6: 77 AAG 036 | E6: 17.02.2026 | F6: 500 g | G6: 224 | H6: 112 | I6: 7 koli × 32
A7: 18.05.2026 | B7: File Market | C7: Narlog Lojistik | D7: 34 AAB 26 | E7: LOT DAĞILIMI TEYİT | F7: 500 g | G7: 2880 | H7: 1440 | I7: 90 koli / soğuk zincir
A8: 04.06.2026 | B8: Samsun Terme Fuarı | C8: Firma aracı | E8: LOT DAĞILIMI TEYİT | F8: 2,5 kg | H8: 114 | I8: Paket adedi kesinleştirilmedi; kg gerçek kayıt
A9: 24.06.2026 | B9: Şehzade Market | C9: Firma aracı | D9: 77 AAG 036 | E9: LOT DAĞILIMI TEYİT | F9: 500 g | G9: 672 | H9: 336 | I9: 21 koli / gerçek sevkiyat
H10: =IF(OR(F10="",G10=""),"",IF(F10="500 g",G10*0.5,IF(F10="2,5 kg",G10*2.5,"")))
H11: =IF(OR(F11="",G11=""),"",IF(F11="500 g",G11*0.5,IF(F11="2,5 kg",G11*2.5,"")))
H12: =IF(OR(F12="",G12=""),"",IF(F12="500 g",G12*0.5,IF(F12="2,5 kg",G12*2.5,"")))
H13: =IF(OR(F13="",G13=""),"",IF(F13="500 g",G13*0.5,IF(F13="2,5 kg",G13*2.5,"")))
H14: =IF(OR(F14="",G14=""),"",IF(F14="500 g",G14*0.5,IF(F14="2,5 kg",G14*2.5,"")))
H15: =IF(OR(F15="",G15=""),"",IF(F15="500 g",G15*0.5,IF(F15="2,5 kg",G15*2.5,"")))
H16: =IF(OR(F16="",G16=""),"",IF(F16="500 g",G16*0.5,IF(F16="2,5 kg",G16*2.5,"")))
H17: =IF(OR(F17="",G17=""),"",IF(F17="500 g",G17*0.5,IF(F17="2,5 kg",G17*2.5,"")))
H18: =IF(OR(F18="",G18=""),"",IF(F18="500 g",G18*0.5,IF(F18="2,5 kg",G18*2.5,"")))
H19: =IF(OR(F19="",G19=""),"",IF(F19="500 g",G19*0.5,IF(F19="2,5 kg",G19*2.5,"")))
H20: =IF(OR(F20="",G20=""),"",IF(F20="500 g",G20*0.5,IF(F20="2,5 kg",G20*2.5,"")))
H21: =IF(OR(F21="",G21=""),"",IF(F21="500 g",G21*0.5,IF(F21="2,5 kg",G21*2.5,"")))
... H501: =IF(OR(F501="",G501=""),"",IF(F501="500 g",G501*0.5,IF(F501="2,5 kg",G501*2.5,"")))

Sheet 24 2026 KÜTLE DENKLİĞİ
A1: Üretim Tarihi | B1: Teorik Üretim kg | C1: Üretim Firesi kg | D1: Net Mamul kg | E1: 500 g Paket kg | F1: 2,5 kg Paket kg | G1: Paketleme Firesi kg | H1: Paketleme Bakiye kg | I1: Sevk Edilen kg | J1: Hesaplanan Paketli Stok kg | K1: Kütle Denkliği Farkı kg | L1: Sonuç | M1: Açıklama | V1: ⌂ ANA SAYFA
A2: ='21 2026 ÜRETİM'!A2 -> 14.01.2026 | B2: =IF(A2="","",'21 2026 ÜRETİM'!D2) -> 244.944 | C2: =IF(A2="","",'21 2026 ÜRETİM'!E2) -> 4 | D2: =IF(A2="","",'21 2026 ÜRETİM'!F2) -> 240.944 | E2: =IF(A2="","",SUMIF('22 2026 PAKETLEME'!$B$2:$B$501,A2,'22 2026 PAKETLEME'!$E$2:$E$501)) -> 0 | F2: =IF(A2="","",SUMIF('22 2026 PAKETLEME'!$B$2:$B$501,A2,'22 2026 PAKETLEME'!$G$2:$G$501)) -> 240 | G2: =IF(A2="","",SUMIF('22 2026 PAKETLEME'!$B$2:$B$501,A2,'22 2026 PAKETLEME'!$H$2:$H$501)) -> 0.944 | H2: =IF(A2="","",D2-E2-F2-G2) -> -1.1546319e-14 | I2: =IF(A2="","",SUMIF('23 2026 SEVKİYAT'!$E$2:$E$501,A2,'23 2026 SEVKİYAT'!$H$2:$H$501)) -> 240 | J2: =IF(A2="","",E2+F2-I2) -> 0 | K2: =IF(A2="","",D2-E2-F2-G2-H2) -> 0 | L2: =IF(A2="","",IF(ABS(K2)<0.001,"KAPALI","KONTROL")) -> KAPALI | M2: =IF(A2="","",IF(J2<0,"SEVK PAKETLEMEYİ AŞIYOR",IF(H2<>0,"PAKETLEME BAKİYESİ VAR","DENKLİK KAPALI"))) -> PAKETLEME BAKİYESİ VAR | V2: → ÜRETİM
A3: ='21 2026 ÜRETİM'!A3 -> 17.02.2026 | B3: =IF(A3="","",'21 2026 ÜRETİM'!D3) -> 224.532 | C3: =IF(A3="","",'21 2026 ÜRETİM'!E3) -> 3 | D3: =IF(A3="","",'21 2026 ÜRETİM'!F3) -> 221.532 | E3: =IF(A3="","",SUMIF('22 2026 PAKETLEME'!$B$2:$B$501,A3,'22 2026 PAKETLEME'!$E$2:$E$501)) -> 176 | F3: =IF(A3="","",SUMIF('22 2026 PAKETLEME'!$B$2:$B$501,A3,'22 2026 PAKETLEME'!$G$2:$G$501)) -> 45 | G3: =IF(A3="","",SUMIF('22 2026 PAKETLEME'!$B$2:$B$501,A3,'22 2026 PAKETLEME'!$H$2:$H$501)) -> 0.532 | H3: =IF(A3="","",D3-E3-F3-G3) -> 1.0658141e-14 | I3: =IF(A3="","",SUMIF('23 2026 SEVKİYAT'!$E$2:$E$501,A3,'23 2026 SEVKİYAT'!$H$2:$H$501)) -> 221 | J3: =IF(A3="","",E3+F3-I3) -> 0 | K3: =IF(A3="","",D3-E3-F3-G3-H3) -> 0 | L3: =IF(A3="","",IF(ABS(K3)<0.001,"KAPALI","KONTROL")) -> KAPALI | M3: =IF(A3="","",IF(J3<0,"SEVK PAKETLEMEYİ AŞIYOR",IF(H3<>0,"PAKETLEME BAKİYESİ VAR","DENKLİK KAPALI"))) -> PAKETLEME BAKİYESİ VAR | V3: → LOT BAĞI
A4: ='21 2026 ÜRETİM'!A4 -> 15.04.2026 | B4: =IF(A4="","",'21 2026 ÜRETİM'!D4) -> 265.356 | C4: =IF(A4="","",'21 2026 ÜRETİM'!E4) -> 5 | D4: =IF(A4="","",'21 2026 ÜRETİM'!F4) -> 260 | E4: =IF(A4="","",SUMIF('22 2026 PAKETLEME'!$B$2:$B$501,A4,'22 2026 PAKETLEME'!$E$2:$E$501)) -> 260 | F4: =IF(A4="","",SUMIF('22 2026 PAKETLEME'!$B$2:$B$501,A4,'22 2026 PAKETLEME'!$G$2:$G$501)) -> 0 | G4: =IF(A4="","",SUMIF('22 2026 PAKETLEME'!$B$2:$B$501,A4,'22 2026 PAKETLEME'!$H$2:$H$501)) -> 0 | H4: =IF(A4="","",D4-E4-F4-G4) -> 0 | I4: =IF(A4="","",SUMIF('23 2026 SEVKİYAT'!$E$2:$E$501,A4,'23 2026 SEVKİYAT'!$H$2:$H$501)) -> 0 | J4: =IF(A4="","",E4+F4-I4) -> 260 | K4: =IF(A4="","",D4-E4-F4-G4-H4) -> 0 | L4: =IF(A4="","",IF(ABS(K4)<0.001,"KAPALI","KONTROL")) -> KAPALI | M4: =IF(A4="","",IF(J4<0,"SEVK PAKETLEMEYİ AŞIYOR",IF(H4<>0,"PAKETLEME BAKİYESİ VAR","DENKLİK KAPALI"))) -> DENKLİK KAPALI
A5: ='21 2026 ÜRETİM'!A5 -> 27.04.2026 | B5: =IF(A5="","",'21 2026 ÜRETİM'!D5) -> 265.356 | C5: =IF(A5="","",'21 2026 ÜRETİM'!E5) -> 4 | D5: =IF(A5="","",'21 2026 ÜRETİM'!F5) -> 261.356 | E5: =IF(A5="","",SUMIF('22 2026 PAKETLEME'!$B$2:$B$501,A5,'22 2026 PAKETLEME'!$E$2:$E$501)) -> 261 | F5: =IF(A5="","",SUMIF('22 2026 PAKETLEME'!$B$2:$B$501,A5,'22 2026 PAKETLEME'!$G$2:$G$501)) -> 0 | G5: =IF(A5="","",SUMIF('22 2026 PAKETLEME'!$B$2:$B$501,A5,'22 2026 PAKETLEME'!$H$2:$H$501)) -> 0.356 | H5: =IF(A5="","",D5-E5-F5-G5) -> -5.4400928e-15 | I5: =IF(A5="","",SUMIF('23 2026 SEVKİYAT'!$E$2:$E$501,A5,'23 2026 SEVKİYAT'!$H$2:$H$501)) -> 0 | J5: =IF(A5="","",E5+F5-I5) -> 261 | K5: =IF(A5="","",D5-E5-F5-G5-H5) -> 0 | L5: =IF(A5="","",IF(ABS(K5)<0.001,"KAPALI","KONTROL")) -> KAPALI | M5: =IF(A5="","",IF(J5<0,"SEVK PAKETLEMEYİ AŞIYOR",IF(H5<>0,"PAKETLEME BAKİYESİ VAR","DENKLİK KAPALI"))) -> PAKETLEME BAKİYESİ VAR
A6: ='21 2026 ÜRETİM'!A6 -> 04.05.2026 | B6: =IF(A6="","",'21 2026 ÜRETİM'!D6) -> 265.356 | C6: =IF(A6="","",'21 2026 ÜRETİM'!E6) -> 6 | D6: =IF(A6="","",'21 2026 ÜRETİM'!F6) -> 259.356 | E6: =IF(A6="","",SUMIF('22 2026 PAKETLEME'!$B$2:$B$501,A6,'22 2026 PAKETLEME'!$E$2:$E$501)) -> 259 | F6: =IF(A6="","",SUMIF('22 2026 PAKETLEME'!$B$2:$B$501,A6,'22 2026 PAKETLEME'!$G$2:$G$501)) -> 0 | G6: =IF(A6="","",SUMIF('22 2026 PAKETLEME'!$B$2:$B$501,A6,'22 2026 PAKETLEME'!$H$2:$H$501)) -> 0.356 | H6: =IF(A6="","",D6-E6-F6-G6) -> -5.4400928e-15 | I6: =IF(A6="","",SUMIF('23 2026 SEVKİYAT'!$E$2:$E$501,A6,'23 2026 SEVKİYAT'!$H$2:$H$501)) -> 0 | J6: =IF(A6="","",E6+F6-I6) -> 259 | K6: =IF(A6="","",D6-E6-F6-G6-H6) -> 0 | L6: =IF(A6="","",IF(ABS(K6)<0.001,"KAPALI","KONTROL")) -> KAPALI | M6: =IF(A6="","",IF(J6<0,"SEVK PAKETLEMEYİ AŞIYOR",IF(H6<>0,"PAKETLEME BAKİYESİ VAR","DENKLİK KAPALI"))) -> PAKETLEME BAKİYESİ VAR
A7: ='21 2026 ÜRETİM'!A7 -> 05.05.2026 | B7: =IF(A7="","",'21 2026 ÜRETİM'!D7) -> 265.356 | C7: =IF(A7="","",'21 2026 ÜRETİM'!E7) -> 5 | D7: =IF(A7="","",'21 2026 ÜRETİM'!F7) -> 260.356 | E7: =IF(A7="","",SUMIF('22 2026 PAKETLEME'!$B$2:$B$501,A7,'22 2026 PAKETLEME'!$E$2:$E$501)) -> 260 | F7: =IF(A7="","",SUMIF('22 2026 PAKETLEME'!$B$2:$B$501,A7,'22 2026 PAKETLEME'!$G$2:$G$501)) -> 0 | G7: =IF(A7="","",SUMIF('22 2026 PAKETLEME'!$B$2:$B$501,A7,'22 2026 PAKETLEME'!$H$2:$H$501)) -> 0.356 | H7: =IF(A7="","",D7-E7-F7-G7) -> -5.4400928e-15 | I7: =IF(A7="","",SUMIF('23 2026 SEVKİYAT'!$E$2:$E$501,A7,'23 2026 SEVKİYAT'!$H$2:$H$501)) -> 0 | J7: =IF(A7="","",E7+F7-I7) -> 260 | K7: =IF(A7="","",D7-E7-F7-G7-H7) -> 0 | L7: =IF(A7="","",IF(ABS(K7)<0.001,"KAPALI","KONTROL")) -> KAPALI | M7: =IF(A7="","",IF(J7<0,"SEVK PAKETLEMEYİ AŞIYOR",IF(H7<>0,"PAKETLEME BAKİYESİ VAR","DENKLİK KAPALI"))) -> PAKETLEME BAKİYESİ VAR
A8: ='21 2026 ÜRETİM'!A8 -> 07.05.2026 | B8: =IF(A8="","",'21 2026 ÜRETİM'!D8) -> 265.356 | C8: =IF(A8="","",'21 2026 ÜRETİM'!E8) -> 6 | D8: =IF(A8="","",'21 2026 ÜRETİM'!F8) -> 259.356 | E8: =IF(A8="","",SUMIF('22 2026 PAKETLEME'!$B$2:$B$501,A8,'22 2026 PAKETLEME'!$E$2:$E$501)) -> 259 | F8: =IF(A8="","",SUMIF('22 2026 PAKETLEME'!$B$2:$B$501,A8,'22 2026 PAKETLEME'!$G$2:$G$501)) -> 0 | G8: =IF(A8="","",SUMIF('22 2026 PAKETLEME'!$B$2:$B$501,A8,'22 2026 PAKETLEME'!$H$2:$H$501)) -> 0.356 | H8: =IF(A8="","",D8-E8-F8-G8) -> -5.4400928e-15 | I8: =IF(A8="","",SUMIF('23 2026 SEVKİYAT'!$E$2:$E$501,A8,'23 2026 SEVKİYAT'!$H$2:$H$501)) -> 0 | J8: =IF(A8="","",E8+F8-I8) -> 259 | K8: =IF(A8="","",D8-E8-F8-G8-H8) -> 0 | L8: =IF(A8="","",IF(ABS(K8)<0.001,"KAPALI","KONTROL")) -> KAPALI | M8: =IF(A8="","",IF(J8<0,"SEVK PAKETLEMEYİ AŞIYOR",IF(H8<>0,"PAKETLEME BAKİYESİ VAR","DENKLİK KAPALI"))) -> PAKETLEME BAKİYESİ VAR
A9: ='21 2026 ÜRETİM'!A9 -> 12.05.2026 | B9: =IF(A9="","",'21 2026 ÜRETİM'!D9) -> 265.356 | C9: =IF(A9="","",'21 2026 ÜRETİM'!E9) -> 5 | D9: =IF(A9="","",'21 2026 ÜRETİM'!F9) -> 260.356 | E9: =IF(A9="","",SUMIF('22 2026 PAKETLEME'!$B$2:$B$501,A9,'22 2026 PAKETLEME'!$E$2:$E$501)) -> 260 | F9: =IF(A9="","",SUMIF('22 2026 PAKETLEME'!$B$2:$B$501,A9,'22 2026 PAKETLEME'!$G$2:$G$501)) -> 0 | G9: =IF(A9="","",SUMIF('22 2026 PAKETLEME'!$B$2:$B$501,A9,'22 2026 PAKETLEME'!$H$2:$H$501)) -> 0.356 | H9: =IF(A9="","",D9-E9-F9-G9) -> -5.4400928e-15 | I9: =IF(A9="","",SUMIF('23 2026 SEVKİYAT'!$E$2:$E$501,A9,'23 2026 SEVKİYAT'!$H$2:$H$501)) -> 0 | J9: =IF(A9="","",E9+F9-I9) -> 260 | K9: =IF(A9="","",D9-E9-F9-G9-H9) -> 0 | L9: =IF(A9="","",IF(ABS(K9)<0.001,"KAPALI","KONTROL")) -> KAPALI | M9: =IF(A9="","",IF(J9<0,"SEVK PAKETLEMEYİ AŞIYOR",IF(H9<>0,"PAKETLEME BAKİYESİ VAR","DENKLİK KAPALI"))) -> PAKETLEME BAKİYESİ VAR
A10: ='21 2026 ÜRETİM'!A10 -> 15.06.2026 | B10: =IF(A10="","",'21 2026 ÜRETİM'!D10) -> 122.472 | C10: =IF(A10="","",'21 2026 ÜRETİM'!E10) -> 40 | D10: =IF(A10="","",'21 2026 ÜRETİM'!F10) -> 82.472 | E10: =IF(A10="","",SUMIF('22 2026 PAKETLEME'!$B$2:$B$501,A10,'22 2026 PAKETLEME'!$E$2:$E$501)) -> 82 | F10: =IF(A10="","",SUMIF('22 2026 PAKETLEME'!$B$2:$B$501,A10,'22 2026 PAKETLEME'!$G$2:$G$501)) -> 0 | G10: =IF(A10="","",SUMIF('22 2026 PAKETLEME'!$B$2:$B$501,A10,'22 2026 PAKETLEME'!$H$2:$H$501)) -> 0.472 | H10: =IF(A10="","",D10-E10-F10-G10) -> -5.7731597e-15 | I10: =IF(A10="","",SUMIF('23 2026 SEVKİYAT'!$E$2:$E$501,A10,'23 2026 SEVKİYAT'!$H$2:$H$501)) -> 0 | J10: =IF(A10="","",E10+F10-I10) -> 82 | K10: =IF(A10="","",D10-E10-F10-G10-H10) -> 0 | L10: =IF(A10="","",IF(ABS(K10)<0.001,"KAPALI","KONTROL")) -> KAPALI | M10: =IF(A10="","",IF(J10<0,"SEVK PAKETLEMEYİ AŞIYOR",IF(H10<>0,"PAKETLEME BAKİYESİ VAR","DENKLİK KAPALI"))) -> PAKETLEME BAKİYESİ VAR
A11: ='21 2026 ÜRETİM'!A11 -> 17.06.2026 | B11: =IF(A11="","",'21 2026 ÜRETİM'!D11) -> 142.884 | C11: =IF(A11="","",'21 2026 ÜRETİM'!E11) -> 15 | D11: =IF(A11="","",'21 2026 ÜRETİM'!F11) -> 127.884 | E11: =IF(A11="","",SUMIF('22 2026 PAKETLEME'!$B$2:$B$501,A11,'22 2026 PAKETLEME'!$E$2:$E$501)) -> 127.5 | F11: =IF(A11="","",SUMIF('22 2026 PAKETLEME'!$B$2:$B$501,A11,'22 2026 PAKETLEME'!$G$2:$G$501)) -> 0 | G11: =IF(A11="","",SUMIF('22 2026 PAKETLEME'!$B$2:$B$501,A11,'22 2026 PAKETLEME'!$H$2:$H$501)) -> 0.384 | H11: =IF(A11="","",D11-E11-F11-G11) -> 3.3306691e-16 | I11: =IF(A11="","",SUMIF('23 2026 SEVKİYAT'!$E$2:$E$501,A11,'23 2026 SEVKİYAT'!$H$2:$H$501)) -> 0 | J11: =IF(A11="","",E11+F11-I11) -> 127.5 | K11: =IF(A11="","",D11-E11-F11-G11-H11) -> 0 | L11: =IF(A11="","",IF(ABS(K11)<0.001,"KAPALI","KONTROL")) -> KAPALI | M11: =IF(A11="","",IF(J11<0,"SEVK PAKETLEMEYİ AŞIYOR",IF(H11<>0,"PAKETLEME BAKİYESİ VAR","DENKLİK KAPALI"))) -> PAKETLEME BAKİYESİ VAR
A12: ='21 2026 ÜRETİM'!A12 -> 23.06.2026 | B12: =IF(A12="","",'21 2026 ÜRETİM'!D12) -> 142.884 | C12: =IF(A12="","",'21 2026 ÜRETİM'!E12) -> 10 | D12: =IF(A12="","",'21 2026 ÜRETİM'!F12) -> 132.884 | E12: =IF(A12="","",SUMIF('22 2026 PAKETLEME'!$B$2:$B$501,A12,'22 2026 PAKETLEME'!$E$2:$E$501)) -> 132.5 | F12: =IF(A12="","",SUMIF('22 2026 PAKETLEME'!$B$2:$B$501,A12,'22 2026 PAKETLEME'!$G$2:$G$501)) -> 0 | G12: =IF(A12="","",SUMIF('22 2026 PAKETLEME'!$B$2:$B$501,A12,'22 2026 PAKETLEME'!$H$2:$H$501)) -> 0.384 | H12: =IF(A12="","",D12-E12-F12-G12) -> -1.3877788e-14 | I12: =IF(A12="","",SUMIF('23 2026 SEVKİYAT'!$E$2:$E$501,A12,'23 2026 SEVKİYAT'!$H$2:$H$501)) -> 0 | J12: =IF(A12="","",E12+F12-I12) -> 132.5 | K12: =IF(A12="","",D12-E12-F12-G12-H12) -> 0 | L12: =IF(A12="","",IF(ABS(K12)<0.001,"KAPALI","KONTROL")) -> KAPALI | M12: =IF(A12="","",IF(J12<0,"SEVK PAKETLEMEYİ AŞIYOR",IF(H12<>0,"PAKETLEME BAKİYESİ VAR","DENKLİK KAPALI"))) -> PAKETLEME BAKİYESİ VAR
A13: ='21 2026 ÜRETİM'!A13 -> 0 | B13: =IF(A13="","",'21 2026 ÜRETİM'!D13) | C13: =IF(A13="","",'21 2026 ÜRETİM'!E13) -> 0 | D13: =IF(A13="","",'21 2026 ÜRETİM'!F13) | E13: =IF(A13="","",SUMIF('22 2026 PAKETLEME'!$B$2:$B$501,A13,'22 2026 PAKETLEME'!$E$2:$E$501)) -> 0 | F13: =IF(A13="","",SUMIF('22 2026 PAKETLEME'!$B$2:$B$501,A13,'22 2026 PAKETLEME'!$G$2:$G$501)) -> 0 | G13: =IF(A13="","",SUMIF('22 2026 PAKETLEME'!$B$2:$B$501,A13,'22 2026 PAKETLEME'!$H$2:$H$501)) -> 0 | H13: =IF(A13="","",D13-E13-F13-G13) -> #VALUE! | I13: =IF(A13="","",SUMIF('23 2026 SEVKİYAT'!$E$2:$E$501,A13,'23 2026 SEVKİYAT'!$H$2:$H$501)) -> 0 | J13: =IF(A13="","",E13+F13-I13) -> 0 | K13: =IF(A13="","",D13-E13-F13-G13-H13) -> #VALUE! | L13: =IF(A13="","",IF(ABS(K13)<0.001,"KAPALI","KONTROL")) -> #VALUE! | M13: =IF(A13="","",IF(J13<0,"SEVK PAKETLEMEYİ AŞIYOR",IF(H13<>0,"PAKETLEME BAKİYESİ VAR","DENKLİK KAPALI"))) -> #VALUE!
A14: ='21 2026 ÜRETİM'!A14 -> 0 | B14: =IF(A14="","",'21 2026 ÜRETİM'!D14) | C14: =IF(A14="","",'21 2026 ÜRETİM'!E14) -> 0 | D14: =IF(A14="","",'21 2026 ÜRETİM'!F14) | E14: =IF(A14="","",SUMIF('22 2026 PAKETLEME'!$B$2:$B$501,A14,'22 2026 PAKETLEME'!$E$2:$E$501)) -> 0 | F14: =IF(A14="","",SUMIF('22 2026 PAKETLEME'!$B$2:$B$501,A14,'22 2026 PAKETLEME'!$G$2:$G$501)) -> 0 | G14: =IF(A14="","",SUMIF('22 2026 PAKETLEME'!$B$2:$B$501,A14,'22 2026 PAKETLEME'!$H$2:$H$501)) -> 0 | H14: =IF(A14="","",D14-E14-F14-G14) -> #VALUE! | I14: =IF(A14="","",SUMIF('23 2026 SEVKİYAT'!$E$2:$E$501,A14,'23 2026 SEVKİYAT'!$H$2:$H$501)) -> 0 | J14: =IF(A14="","",E14+F14-I14) -> 0 | K14: =IF(A14="","",D14-E14-F14-G14-H14) -> #VALUE! | L14: =IF(A14="","",IF(ABS(K14)<0.001,"KAPALI","KONTROL")) -> #VALUE! | M14: =IF(A14="","",IF(J14<0,"SEVK PAKETLEMEYİ AŞIYOR",IF(H14<>0,"PAKETLEME BAKİYESİ VAR","DENKLİK KAPALI"))) -> #VALUE!
A15: ='21 2026 ÜRETİM'!A15 -> 0 | B15: =IF(A15="","",'21 2026 ÜRETİM'!D15) | C15: =IF(A15="","",'21 2026 ÜRETİM'!E15) -> 0 | D15: =IF(A15="","",'21 2026 ÜRETİM'!F15) | E15: =IF(A15="","",SUMIF('22 2026 PAKETLEME'!$B$2:$B$501,A15,'22 2026 PAKETLEME'!$E$2:$E$501)) -> 0 | F15: =IF(A15="","",SUMIF('22 2026 PAKETLEME'!$B$2:$B$501,A15,'22 2026 PAKETLEME'!$G$2:$G$501)) -> 0 | G15: =IF(A15="","",SUMIF('22 2026 PAKETLEME'!$B$2:$B$501,A15,'22 2026 PAKETLEME'!$H$2:$H$501)) -> 0 | H15: =IF(A15="","",D15-E15-F15-G15) -> #VALUE! | I15: =IF(A15="","",SUMIF('23 2026 SEVKİYAT'!$E$2:$E$501,A15,'23 2026 SEVKİYAT'!$H$2:$H$501)) -> 0 | J15: =IF(A15="","",E15+F15-I15) -> 0 | K15: =IF(A15="","",D15-E15-F15-G15-H15) -> #VALUE! | L15: =IF(A15="","",IF(ABS(K15)<0.001,"KAPALI","KONTROL")) -> #VALUE! | M15: =IF(A15="","",IF(J15<0,"SEVK PAKETLEMEYİ AŞIYOR",IF(H15<>0,"PAKETLEME BAKİYESİ VAR","DENKLİK KAPALI"))) -> #VALUE!
... A501: ='21 2026 ÜRETİM'!A501 -> 0 | B501: =IF(A501="","",'21 2026 ÜRETİM'!D501) | C501: =IF(A501="","",'21 2026 ÜRETİM'!E501) -> 0 | D501: =IF(A501="","",'21 2026 ÜRETİM'!F501) | E501: =IF(A501="","",SUMIF('22 2026 PAKETLEME'!$B$2:$B$501,A501,'22 2026 PAKETLEME'!$E$2:$E$501)) -> 0 | F501: =IF(A501="","",SUMIF('22 2026 PAKETLEME'!$B$2:$B$501,A501,'22 2026 PAKETLEME'!$G$2:$G$501)) -> 0 | G501: =IF(A501="","",SUMIF('22 2026 PAKETLEME'!$B$2:$B$501,A501,'22 2026 PAKETLEME'!$H$2:$H$501)) -> 0 | H501: =IF(A501="","",D501-E501-F501-G501) -> #VALUE! | I501: =IF(A501="","",SUMIF('23 2026 SEVKİYAT'!$E$2:$E$501,A501,'23 2026 SEVKİYAT'!$H$2:$H$501)) -> 0 | J501: =IF(A501="","",E501+F501-I501) -> 0 | K501: =IF(A501="","",D501-E501-F501-G501-H501) -> #VALUE! | L501: =IF(A501="","",IF(ABS(K501)<0.001,"KAPALI","KONTROL")) -> #VALUE! | M501: =IF(A501="","",IF(J501<0,"SEVK PAKETLEMEYİ AŞIYOR",IF(H501<>0,"PAKETLEME BAKİYESİ VAR","DENKLİK KAPALI"))) -> #VALUE!

Sheet 25 2026 LOT BAĞI
A1: Üretim Tarihi | B1: Üretim Lot No | C1: Patates unu Lot | D1: Mısır nişastası Lot | E1: Tat mısır unu Lot | F1: Savour Lot | G1: Sarımsak tozu Lot | H1: Karabiber Lot | I1: Tuz Lot | J1: BENECEL A4M Lot | K1: Kontrol Eden | L1: Açıklama | M1: Patates unu | N1: Mısır nişastası | O1: Tat mısır unu | P1: Savour tavuk çeşnisi | Q1: Sarımsak tozu | R1: Karabiber | S1: Tuz | T1: BENECEL A4M | V1: ⌂ ANA SAYFA
A2: 14.01.2026 | B2: 270114 | C2: 251011 | D2: 57108774 | E2: 9222 | G2: 040126-141 | H2: 170126-678 | I2: 20423 | J2: 2743063 | K2: Eda Ayaz | L2: EKSİK LOT | M2: 251011 | N2: 57108774 | O2: 9222 | P2: 01.09.EY | Q2: 040126-141 | R2: 170126-678 | S2: 20423 | T2: 2743063 | V2: → ÜRETİM
A3: 17.02.2026 | B3: 270217 | C3: 251011 | D3: 57108774 | E3: 9222 | G3: 040126-141 | H3: 170126-678 | I3: 20423 | J3: 2743063 | K3: Eda Ayaz | L3: EKSİK LOT | M3: 251212 | N3: 58138875 | O3: 8825 | Q3: 170226-157 | R3: 161125-567 | S3: 20425 | V3: → LOT BAĞI
A4: 15.04.2026 | B4: 270415 | C4: 251212 | D4: 58138875 | E4: 9226 | F4: 01.09.EY | G4: 170226-157 | H4: 070426-693 | I4: 20425 | J4: 2743063 | K4: Eda Ayaz | L4: LOT BAĞI TAMAM | O4: 9226 | R4: 070426-693
A5: 27.04.2026 | B5: 270427 | C5: 251212 | D5: 58138875 | E5: 9226 | F5: 01.09.EY | G5: 170226-157 | H5: 070426-693 | I5: 20425 | J5: 2743063 | K5: Eda Ayaz | L5: LOT BAĞI TAMAM
A6: 04.05.2026 | B6: 270504 | C6: 251212 | D6: 58138875 | E6: 9226 | F6: 01.09.EY | G6: 170226-157 | H6: 070426-693 | I6: 20425 | J6: 2743063 | K6: Eda Ayaz | L6: LOT BAĞI TAMAM
A7: 05.05.2026 | B7: 270505 | C7: 251212 | D7: 58138875 | E7: 9226 | F7: 01.09.EY | G7: 170226-157 | H7: 070426-693 | I7: 20425 | J7: 2743063 | K7: Eda Ayaz | L7: LOT BAĞI TAMAM
A8: 07.05.2026 | B8: 270507 | C8: 251212 | D8: 58138875 | E8: 9226 | F8: 01.09.EY | G8: 170226-157 | H8: 070426-693 | I8: 20425 | J8: 2743063 | K8: Eda Ayaz | L8: LOT BAĞI TAMAM
A9: 12.05.2026 | B9: 270512 | C9: 251212 | D9: 58138875 | E9: 9226 | F9: 01.09.EY | G9: 170226-157 | H9: 070426-693 | I9: 20425 | J9: 2743063 | K9: Eda Ayaz | L9: LOT BAĞI TAMAM
A10: 15.06.2026 | B10: 270615 | C10: 251212 | D10: 58138875 | E10: 9226 | F10: 01.09.EY | G10: 170226-157 | H10: 070426-693 | I10: 20425 | J10: 2743063 | K10: Eda Ayaz | L10: LOT BAĞI TAMAM
A11: 17.06.2026 | B11: 270617 | C11: 251212 | D11: 58138875 | E11: 9226 | F11: 01.09.EY | G11: 170226-157 | H11: 070426-693 | I11: 20425 | J11: 2743063 | K11: Eda Ayaz | L11: LOT BAĞI TAMAM
A12: 23.06.2026 | B12: 270623 | C12: 251212 | D12: 58138875 | E12: 9226 | F12: 01.09.EY | G12: 170226-157 | H12: 070426-693 | I12: 20425 | J12: 2743063 | K12: Eda Ayaz | L12: LOT BAĞI TAMAM
K13: Eda Ayaz
K14: Eda Ayaz
K15: Eda Ayaz
K16: Eda Ayaz
K17: Eda Ayaz
K18: Eda Ayaz
K19: Eda Ayaz
K20: Eda Ayaz
K21: Eda Ayaz
K22: Eda Ayaz
K23: Eda Ayaz
K24: Eda Ayaz
... K501: Eda Ayaz

Sheet 26 2026 TEMİZLİK
A1: Tarih | B1: Bağlı Üretim Lotu | C1: Alan / Ekipman | D1: Temizlik Zamanı | E1: Kullanılan Kimyasal | F1: Temizliği Yapan | G1: Durum | H1: Açıklama | V1: ⌂ ANA SAYFA
A2: 15.04.2026 | B2: 270415 | C2: Mikser/hamur yoğurma, şekillendirme makinesi, tepsileme makinesi, çalışma yüzeyleri ve üretim yapılan zemin | D2: Üretim sonrası | E2: Köpük deterjan ve dezenfektan | F2: Fatih Ayaz / Eda Ayaz | G2: Tamamlandı | H2: Üretim yapılan alan ve ekipmanlar | V2: → ÜRETİM
A3: 27.04.2026 | B3: 270427 | C3: Mikser/hamur yoğurma, şekillendirme makinesi, tepsileme makinesi, çalışma yüzeyleri ve üretim yapılan zemin | D3: Üretim sonrası | E3: Köpük deterjan ve dezenfektan | F3: Fatih Ayaz / Eda Ayaz | G3: Tamamlandı | H3: Üretim yapılan alan ve ekipmanlar | V3: → LOT BAĞI
A4: 04.05.2026 | B4: 270504 | C4: Mikser/hamur yoğurma, şekillendirme makinesi, tepsileme makinesi, çalışma yüzeyleri ve üretim yapılan zemin | D4: Üretim sonrası | E4: Köpük deterjan ve dezenfektan | F4: Fatih Ayaz / Eda Ayaz | G4: Tamamlandı | H4: Üretim yapılan alan ve ekipmanlar
A5: 05.05.2026 | B5: 270505 | C5: Mikser/hamur yoğurma, şekillendirme makinesi, tepsileme makinesi, çalışma yüzeyleri ve üretim yapılan zemin | D5: Üretim sonrası | E5: Köpük deterjan ve dezenfektan | F5: Fatih Ayaz / Eda Ayaz | G5: Tamamlandı | H5: Üretim yapılan alan ve ekipmanlar
A6: 07.05.2026 | B6: 270507 | C6: Mikser/hamur yoğurma, şekillendirme makinesi, tepsileme makinesi, çalışma yüzeyleri ve üretim yapılan zemin | D6: Üretim sonrası | E6: Köpük deterjan ve dezenfektan | F6: Fatih Ayaz / Eda Ayaz | G6: Tamamlandı | H6: Üretim yapılan alan ve ekipmanlar
A7: 12.05.2026 | B7: 270512 | C7: Mikser/hamur yoğurma, şekillendirme makinesi, tepsileme makinesi, çalışma yüzeyleri ve üretim yapılan zemin | D7: Üretim sonrası | E7: Köpük deterjan ve dezenfektan | F7: Fatih Ayaz / Eda Ayaz | G7: Tamamlandı | H7: Üretim yapılan alan ve ekipmanlar
A8: 15.06.2026 | B8: 270615 | C8: Mikser/hamur yoğurma, şekillendirme makinesi, tepsileme makinesi, çalışma yüzeyleri ve üretim yapılan zemin | D8: Üretim sonrası | E8: Köpük deterjan ve dezenfektan | F8: Fatih Ayaz / Eda Ayaz | G8: Tamamlandı | H8: Üretim yapılan alan ve ekipmanlar
A9: 17.06.2026 | B9: 270617 | C9: Mikser/hamur yoğurma, şekillendirme makinesi, tepsileme makinesi, çalışma yüzeyleri ve üretim yapılan zemin | D9: Üretim sonrası | E9: Köpük deterjan ve dezenfektan | F9: Fatih Ayaz / Eda Ayaz | G9: Tamamlandı | H9: Üretim yapılan alan ve ekipmanlar
A10: 23.06.2026 | B10: 270623 | C10: Mikser/hamur yoğurma, şekillendirme makinesi, tepsileme makinesi, çalışma yüzeyleri ve üretim yapılan zemin | D10: Üretim sonrası | E10: Köpük deterjan ve dezenfektan | F10: Fatih Ayaz / Eda Ayaz | G10: Tamamlandı | H10: Üretim yapılan alan ve ekipmanlar
A11: =IF(B11="","",IFERROR(INDEX('21 2026 ÜRETİM'!$A$2:$A$501,MATCH(B11,'21 2026 ÜRETİM'!$G$2:$G$501,0)),""))
A12: =IF(B12="","",IFERROR(INDEX('21 2026 ÜRETİM'!$A$2:$A$501,MATCH(B12,'21 2026 ÜRETİM'!$G$2:$G$501,0)),""))
A13: =IF(B13="","",IFERROR(INDEX('21 2026 ÜRETİM'!$A$2:$A$501,MATCH(B13,'21 2026 ÜRETİM'!$G$2:$G$501,0)),""))
A14: =IF(B14="","",IFERROR(INDEX('21 2026 ÜRETİM'!$A$2:$A$501,MATCH(B14,'21 2026 ÜRETİM'!$G$2:$G$501,0)),""))
A15: =IF(B15="","",IFERROR(INDEX('21 2026 ÜRETİM'!$A$2:$A$501,MATCH(B15,'21 2026 ÜRETİM'!$G$2:$G$501,0)),""))
A16: =IF(B16="","",IFERROR(INDEX('21 2026 ÜRETİM'!$A$2:$A$501,MATCH(B16,'21 2026 ÜRETİM'!$G$2:$G$501,0)),""))
A17: =IF(B17="","",IFERROR(INDEX('21 2026 ÜRETİM'!$A$2:$A$501,MATCH(B17,'21 2026 ÜRETİM'!$G$2:$G$501,0)),""))
A18: =IF(B18="","",IFERROR(INDEX('21 2026 ÜRETİM'!$A$2:$A$501,MATCH(B18,'21 2026 ÜRETİM'!$G$2:$G$501,0)),""))
A19: =IF(B19="","",IFERROR(INDEX('21 2026 ÜRETİM'!$A$2:$A$501,MATCH(B19,'21 2026 ÜRETİM'!$G$2:$G$501,0)),""))
A20: =IF(B20="","",IFERROR(INDEX('21 2026 ÜRETİM'!$A$2:$A$501,MATCH(B20,'21 2026 ÜRETİM'!$G$2:$G$501,0)),""))
A21: =IF(B21="","",IFERROR(INDEX('21 2026 ÜRETİM'!$A$2:$A$501,MATCH(B21,'21 2026 ÜRETİM'!$G$2:$G$501,0)),""))
A22: =IF(B22="","",IFERROR(INDEX('21 2026 ÜRETİM'!$A$2:$A$501,MATCH(B22,'21 2026 ÜRETİM'!$G$2:$G$501,0)),""))
... A501: =IF(B501="","",IFERROR(INDEX('21 2026 ÜRETİM'!$A$2:$A$501,MATCH(B501,'21 2026 ÜRETİM'!$G$2:$G$501,0)),""))

Sheet 98 ÇAPRAZ KONTROL
A1: Üretim Tarihi | B1: Teorik kg | C1: Net Mamul kg | D1: Paketlenen kg | E1: Sevk kg | F1: Paketli Stok kg | G1: Paketleme Bakiye kg | H1: Kütle Farkı kg | I1: Kontrol Sonucu
A2: 14.01.2026 | B2: 244.944 | C2: 240.944 | D2: 240 | E2: 240 | F2: 0 | G2: 0 | H2: 0 | I2: UYGUN
A3: 17.02.2026 | B3: 224.532 | C3: 221.532 | D3: 221 | E3: 221 | F3: 0 | G3: 0 | H3: 0 | I3: UYGUN
A5: ÇAPRAZ KONTROL SONUCU
A6: 14.01.2026 üretimi: 240,000 kg paketlenmiş ürünün tamamı 100 kg ALEK + 140 kg festival/fuar hareketiyle kapanıyor.
A7: 17.02.2026 üretimi: 221,000 kg paketlenmiş ürünün tamamı 64 kg + 45 kg + 112 kg sevkiyatla kapanıyor.
A8: Her iki üretimde paketleme öncesi bakiye, kayıtlı paketleme firesiyle birlikte matematiksel olarak sıfırlanıyor. Kütle farkı 0,000 kg.

Sheet 99 KULLANIM
A1: KULLANIM KURALI
A2: ANA AKIŞ | B2: 00 ANA SAYFA → 20 DEPO KABUL → 21 ÜRETİM → 22 PAKETLEME → 23 SEVKİYAT → 24 KÜTLE DENKLİĞİ → 25 LOT BAĞI → 26 TEMİZLİK
A3: DEPO KABUL | B3: Hammaddeyi açılır listeden seç. Tedarikçi ve birim otomatik gelir. Lotu yalnız kabulde bir kez yaz.
A4: ÜRETİM | B4: Tarih, parti ve gerçek üretim firesini gir. kg/parti, teorik kg, net mamul ve üretim lotu otomatik oluşur.
A5: PAKETLEME | B5: Üretim tarihini listeden seç. Paketleme tarihi ertesi gün, net mamul ve paket kg hesapları otomatik gelir. Sadece paket adetleri ve gerçek paketleme firesini gir.
A6: SEVKİYAT | B6: Üretim bağını ve ambalajı listeden seç. Paket adedi girildiğinde kg otomatik hesaplanır.
A7: LOT BAĞI | B7: Her üretim tek satırdır. Aynı üretim lotunu 8 kez tekrar yazma. Mevcut lot bağları konsolide edildi.
A8: TEMİZLİK | B8: Üretim lotunu seç. Tarih ve standart üretim sonrası temizlik alanları otomatik gelir.
A9: 2025 | B9: Kapanmış tarihsel dönemdir; değiştirme.
A10: KURAL | B10: Sarı/açık giriş alanlarına gerçek veri gir. Geçmişe dönük tahmini kayıt oluşturma.
A11: REV10 DÜZELTME | B11: 21 ÜRETİM ve 23 SEVKİYAT sayfalarında 502+ satırlara taşınmış mükerrer veri blokları kaldırıldı; gerçek kayıtlar üstte tek blokta konsolide edildi.
A12: REV12 LOT SEÇİMİ | B12: 25 LOT BAĞI: her hammadde sütununda yalnız 20 DEPO KABUL'de o hammadde için kayıtlı lotlar açılır listede görünür. Lot tekrar yazılmaz; seçilir. BENECEL kabul lotu 2743063 olarak düzeltildi.
A13: REV13 DÜZELTME | B13: Lot bağı içinde fiilen kullanılan ancak depo kabul listesinden düşmüş tarihsel lotlar depo kabul lot havuzuna geri alındı. Teyitsiz kabul tarihleri uydurulmadı; notla işaretlendi. Ana panel üretim günü COUNTA ile düzeltildi ve sevk noktası SUMIF satır referansları düzeltildi.

Sheet 97 LOT BAĞI ESKİ
A1: Üretim Tarihi | B1: Üretim Lot No | C1: Hammadde Lot No | D1: Hammadde Otomatik | E1: Kullanılan Miktar | F1: Birim | G1: ÜRT Otomatik | H1: SKT Otomatik | I1: Kontrol Eden | J1: Açıklama
A2: 14.01.2026 | B2: 270114 | C2: 251011 | D2: Patates unu | G2: 02.01.2026 | H2: 11.10.2026 | J2: Geçmiş kayıt lot bağı
A3: 14.01.2026 | B3: 270114 | C3: 57108774 | D3: Mısır nişastası | G3: 05.01.2026 | H3: 05.01.2028 | J3: Geçmiş kayıt lot bağı
A4: 14.01.2026 | B4: 270114 | C4: 2732248 | D4: BENECEL | G4: 14.08.2025 | H4: 14.08.2027 | J4: Geçmiş kayıt lot bağı
A5: 14.01.2026 | B5: 270114 | C5: 20423 | D5: Tuz | G5: 16.11.2025 | H5: 16.11.2029 | J5: Geçmiş kayıt lot bağı
A6: 14.01.2026 | B6: 270114 | C6: 9222 | D6: Mısır unu | G6: 13.01.2026 | H6: 13.01.2027 | J6: Geçmiş kayıt lot bağı
A7: 14.01.2026 | B7: 270114 | C7: 170126-678 | D7: Karabiber | G7: 17.01.2026 | H7: 17.01.2028 | J7: Geçmiş kayıt lot bağı
A8: 14.01.2026 | B8: 270114 | C8: 040126-141 | D8: Sarımsak tozu | G8: 04.01.2026 | H8: 04.01.2028 | J8: Geçmiş kayıt lot bağı
A9: 17.02.2026 | B9: 270217 | C9: 251011 | D9: Patates unu | G9: 02.01.2026 | H9: 11.10.2026 | J9: Geçmiş kayıt lot bağı
A10: 17.02.2026 | B10: 270217 | C10: 57108774 | D10: Mısır nişastası | G10: 05.01.2026 | H10: 05.01.2028 | J10: Geçmiş kayıt lot bağı
A11: 17.02.2026 | B11: 270217 | C11: 2732248 | D11: BENECEL | G11: 14.08.2025 | H11: 14.08.2027 | J11: Geçmiş kayıt lot bağı
A12: 17.02.2026 | B12: 270217 | C12: 20423 | D12: Tuz | G12: 16.11.2025 | H12: 16.11.2029 | J12: Geçmiş kayıt lot bağı
A13: 17.02.2026 | B13: 270217 | C13: 9222 | D13: Mısır unu | G13: 13.01.2026 | H13: 13.01.2027 | J13: Geçmiş kayıt lot bağı
... A22: 15.04.2026 | B22: 270415 | C22: 280108-234 | D22: BENECEL | G22: 08.01.2026 | H22: 08.01.2028 | J22: 2026 üretim lot bağı
A23: 15.04.2026 | B23: 270415 | C23: 01.09.EY | D23: Savour tavuk çeşnisi | H23: 09.2026 | J23: 2026 üretim lot bağı
A24: 27.04.2026 | B24: 270427 | C24: 251212 | D24: Patates unu | G24: 12.12.2025 | H24: 12.12.2026 | J24: 2026 üretim lot bağı
A25: 27.04.2026 | B25: 270427 | C25: 58138875 | D25: Mısır nişastası | G25: 09.09.2025 | H25: 09.09.2027 | J25: 2026 üretim lot bağı
A26: 27.04.2026 | B26: 270427 | C26: 9226 | D26: Mısır unu | G26: 20.02.2026 | H26: 20.02.2027 | J26: 2026 üretim lot bağı
A27: 27.04.2026 | B27: 270427 | C27: 20425 | D27: Tuz | G27: 23.07.2025 | H27: 23.07.2026 | J27: 2026 üretim lot bağı
A28: 27.04.2026 | B28: 270427 | C28: 070426-693 | D28: Karabiber | G28: 07.04.2026 | H28: 07.04.2028 | J28: 2026 üretim lot bağı
A29: 27.04.2026 | B29: 270427 | C29: 170226-157 | D29: Sarımsak tozu | G29: 17.02.2026 | H29: 17.02.2028 | J29: 2026 üretim lot bağı
A30: 27.04.2026 | B30: 270427 | C30: 280108-234 | D30: BENECEL | G30: 08.01.2026 | H30: 08.01.2028 | J30: 2026 üretim lot bağı
A31: 27.04.2026 | B31: 270427 | C31: 01.09.EY | D31: Savour tavuk çeşnisi | H31: 09.2026 | J31: 2026 üretim lot bağı
A32: 04.05.2026 | B32: 270504 | C32: 251212 | D32: Patates unu | G32: 12.12.2025 | H32: 12.12.2026 | J32: 2026 üretim lot bağı
A33: 04.05.2026 | B33: 270504 | C33: 58138875 | D33: Mısır nişastası | G33: 09.09.2025 | H33: 09.09.2027 | J33: 2026 üretim lot bağı
